Workbook

Sheet Gifts
A1: BIRTHDAYS | P1: EVENTS
A2: Birthdays / Card 2021 | B2: Birth Date | D2: Death | E2: Current Age | F2: Gift Value | G2: Ideas | H2: Done? | I2: Spent | J2: Remaining | K2: Total spend | L2: Target | M2: Actual | N2: Time | P2: Month | Q2: Date | R2: Amount | S2: Ideas | T2: Spent | U2: Remaining
A3: JAN | B3: =SUM(F4:F12) -> 30 | J3: =SUM(J4:J12) -> -5 | K3: =SUM(B3,R3) -> 140 | L3: =($F$105/12)-K3 -> 95 | M3: =IF(N3<>"",N3,($F$105/12)-(B3-R3)+(J3+U3)) -> 275.43 | N3: 275.43 | P3: JAN | R3: =SUM(R4:R12) -> 110 | U3: =SUM(U4:U12) -> 110
A4: Ruby | B4: 43102 | E4: =DATEDIF(B4,NOW(),"y") -> 8 | F4: 20
A5: Sam | B5: 39453 | C5: =TEXT(B5,"MMDD") -> 0106 | E5: =DATEDIF(B5,NOW(),"y") -> 18 | F5: 10 | G5: Cash | H5: Y | I5: 10 | J5: =IF(N5="MISSED",F5,F5-I5) -> 0 | N5: =IF(TEXT(TODAY(),"YYYY")=RIGHT(A$2,4), IF(ISERROR(DATEDIF(TEXT(TODAY(),"dd/mm/yyyy"),TEXT(B5,"dd/mm/")&RIGHT(A$2,4),"d")),IF(H5="Y","DONE","MISSED"), IF(DATEDIF(TEXT(TODAY(),"dd/mm/yyyy"),TEXT(B5,"dd/mm/")&RIGHT(A$2,4),"d") = 0,"TODAY!!!", IF(DATEDIF(TEXT(TODAY(),"dd/mm/yyyy"),TEXT(B5,"dd/mm/")&RIGHT(A$2,4),"d") > 0, DATEDIF(TEXT(TODAY(),"dd/mm/yyyy"), TEXT(B5,"dd/mm/")&RIGHT(A$2,4),"d")&" Days to go!",""))),"") | P5: NY Gifts | Q5: 1 | R5: 110 | U5: =R5-T5 -> 110
A6: Jamie | B6: =DATE(1990,1,6) -> 32879 | C6: =TEXT(B6,"MMDD") -> 0106 | E6: =DATEDIF(B6,NOW(),"y") -> 36 | F6: 0 | J6: =IF(N6="MISSED",F6,F6-I6) -> 0 | N6: =IF(TEXT(TODAY(),"YYYY")=RIGHT(A$2,4), IF(ISERROR(DATEDIF(TEXT(TODAY(),"dd/mm/yyyy"),TEXT(B6,"dd/mm/")&RIGHT(A$2,4),"d")),IF(H6="Y","DONE","MISSED"), IF(DATEDIF(TEXT(TODAY(),"dd/mm/yyyy"),TEXT(B6,"dd/mm/")&RIGHT(A$2,4),"d") = 0,"TODAY!!!", IF(DATEDIF(TEXT(TODAY(),"dd/mm/yyyy"),TEXT(B6,"dd/mm/")&RIGHT(A$2,4),"d") > 0, DATEDIF(TEXT(TODAY(),"dd/mm/yyyy"), TEXT(B6,"dd/mm/")&RIGHT(A$2,4),"d")&" Days to go!",""))),"")
A7: Amanda | B7: 42376 | C7: =TEXT(B7,"MMDD") -> 0107 | E7: =DATEDIF(B7,NOW(),"y") -> 10 | F7: 0 | J7: =IF(N7="MISSED",F7,F7-I7) -> 0 | N7: =IF(TEXT(TODAY(),"YYYY")=RIGHT(A$2,4), IF(ISERROR(DATEDIF(TEXT(TODAY(),"dd/mm/yyyy"),TEXT(B7,"dd/mm/")&RIGHT(A$2,4),"d")),IF(H7="Y","DONE","MISSED"), IF(DATEDIF(TEXT(TODAY(),"dd/mm/yyyy"),TEXT(B7,"dd/mm/")&RIGHT(A$2,4),"d") = 0,"TODAY!!!", IF(DATEDIF(TEXT(TODAY(),"dd/mm/yyyy"),TEXT(B7,"dd/mm/")&RIGHT(A$2,4),"d") > 0, DATEDIF(TEXT(TODAY(),"dd/mm/yyyy"), TEXT(B7,"dd/mm/")&RIGHT(A$2,4),"d")&" Days to go!",""))),"")
A8: Uncle Andrew (Auntie Julie) | B8: 42378 | C8: =TEXT(B8,"MMDD") -> 0109 | E8: =DATEDIF(B8,NOW(),"y") -> 10 | F8: 0 | H8: Y | I8: 5 | J8: =IF(N8="MISSED",F8,F8-I8) -> -5 | N8: =IF(TEXT(TODAY(),"YYYY")=RIGHT(A$2,4), IF(ISERROR(DATEDIF(TEXT(TODAY(),"dd/mm/yyyy"),TEXT(B8,"dd/mm/")&RIGHT(A$2,4),"d")),IF(H8="Y","DONE","MISSED"), IF(DATEDIF(TEXT(TODAY(),"dd/mm/yyyy"),TEXT(B8,"dd/mm/")&RIGHT(A$2,4),"d") = 0,"TODAY!!!", IF(DATEDIF(TEXT(TODAY(),"dd/mm/yyyy"),TEXT(B8,"dd/mm/")&RIGHT(A$2,4),"d") > 0, DATEDIF(TEXT(TODAY(),"dd/mm/yyyy"), TEXT(B8,"dd/mm/")&RIGHT(A$2,4),"d")&" Days to go!",""))),"")
A9: Uncle Andrew (JJ) (RIP) | B9: 42382 | C9: =TEXT(B9,"MMDD") -> 0113 | E9: =DATEDIF(B9,NOW(),"y") -> 10 | F9: 0 | J9: =IF(N9="MISSED",F9,F9-I9) -> 0 | N9: =IF(TEXT(TODAY(),"YYYY")=RIGHT(A$2,4), IF(ISERROR(DATEDIF(TEXT(TODAY(),"dd/mm/yyyy"),TEXT(B9,"dd/mm/")&RIGHT(A$2,4),"d")),IF(H9="Y","DONE","MISSED"), IF(DATEDIF(TEXT(TODAY(),"dd/mm/yyyy"),TEXT(B9,"dd/mm/")&RIGHT(A$2,4),"d") = 0,"TODAY!!!", IF(DATEDIF(TEXT(TODAY(),"dd/mm/yyyy"),TEXT(B9,"dd/mm/")&RIGHT(A$2,4),"d") > 0, DATEDIF(TEXT(TODAY(),"dd/mm/yyyy"), TEXT(B9,"dd/mm/")&RIGHT(A$2,4),"d")&" Days to go!",""))),"")
A10: Rachel | B10: 42383 | C10: =TEXT(B10,"MMDD") -> 0114 | E10: =DATEDIF(B10,NOW(),"y") -> 10 | F10: 0 | J10: =IF(N10="MISSED",F10,F10-I10) -> 0 | N10: =IF(TEXT(TODAY(),"YYYY")=RIGHT(A$2,4), IF(ISERROR(DATEDIF(TEXT(TODAY(),"dd/mm/yyyy"),TEXT(B10,"dd/mm/")&RIGHT(A$2,4),"d")),IF(H10="Y","DONE","MISSED"), IF(DATEDIF(TEXT(TODAY(),"dd/mm/yyyy"),TEXT(B10,"dd/mm/")&RIGHT(A$2,4),"d") = 0,"TODAY!!!", IF(DATEDIF(TEXT(TODAY(),"dd/mm/yyyy"),TEXT(B10,"dd/mm/")&RIGHT(A$2,4),"d") > 0, DATEDIF(TEXT(TODAY(),"dd/mm/yyyy"), TEXT(B10,"dd/mm/")&RIGHT(A$2,4),"d")&" Days to go!",""))),"")
A11: Auntie Susan | B11: 20115 | C11: =TEXT(B11,"MMDD") -> 0126 | E11: =DATEDIF(B11,NOW(),"y") -> 71 | F11: 0 | J11: =IF(N11="MISSED",F11,F11-I11) -> 0 | N11: =IF(TEXT(TODAY(),"YYYY")=RIGHT(A$2,4), IF(ISERROR(DATEDIF(TEXT(TODAY(),"dd/mm/yyyy"),TEXT(B11,"dd/mm/")&RIGHT(A$2,4),"d")),IF(H11="Y","DONE","MISSED"), IF(DATEDIF(TEXT(TODAY(),"dd/mm/yyyy"),TEXT(B11,"dd/mm/")&RIGHT(A$2,4),"d") = 0,"TODAY!!!", IF(DATEDIF(TEXT(TODAY(),"dd/mm/yyyy"),TEXT(B11,"dd/mm/")&RIGHT(A$2,4),"d") > 0, DATEDIF(TEXT(TODAY(),"dd/mm/yyyy"), TEXT(B11,"dd/mm/")&RIGHT(A$2,4),"d")&" Days to go!",""))),"")
A12: Malcolm | B12: 42396 | C12: =TEXT(B12,"MMDD") -> 0127 | E12: =DATEDIF(B12,NOW(),"y") -> 10 | F12: 0 | J12: =IF(N12="MISSED",F12,F12-I12) -> 0 | N12: =IF(TEXT(TODAY(),"YYYY")=RIGHT(A$2,4), IF(ISERROR(DATEDIF(TEXT(TODAY(),"dd/mm/yyyy"),TEXT(B12,"dd/mm/")&RIGHT(A$2,4),"d")),IF(H12="Y","DONE","MISSED"), IF(DATEDIF(TEXT(TODAY(),"dd/mm/yyyy"),TEXT(B12,"dd/mm/")&RIGHT(A$2,4),"d") = 0,"TODAY!!!", IF(DATEDIF(TEXT(TODAY(),"dd/mm/yyyy"),TEXT(B12,"dd/mm/")&RIGHT(A$2,4),"d") > 0, DATEDIF(TEXT(TODAY(),"dd/mm/yyyy"), TEXT(B12,"dd/mm/")&RIGHT(A$2,4),"d")&" Days to go!",""))),"")
A14: FEB | B14: =SUM(F15:F19) -> 30 | J14: =SUM(J15:J19) -> -25.99 | K14: =SUM(B14,R14) -> 80 | L14: =L3+($F$105/12)-B14-R14 -> 250 | M14: =IF(N14<>"",N14,(M3+($F$105/12))-B14-R14+(J14+U14)) -> 454.44 | P14: FEB | R14: =SUM(R15:R19) -> 50 | U14: =SUM(U15:U19) -> 50
A15: Uncle Keith | B15: 42401 | C15: =TEXT(B15,"MMDD") -> 0201 | E15: =DATEDIF(B15,NOW(),"y") -> 10 | F15: 0 | G15: Beer | J15: =IF(N15="MISSED",F15,F15-I15) -> 0 | N15: =IF(TEXT(TODAY(),"YYYY")=RIGHT(A$2,4), IF(ISERROR(DATEDIF(TEXT(TODAY(),"dd/mm/yyyy"),TEXT(B15,"dd/mm/")&RIGHT(A$2,4),"d")),IF(H15="Y","DONE","MISSED"), IF(DATEDIF(TEXT(TODAY(),"dd/mm/yyyy"),TEXT(B15,"dd/mm/")&RIGHT(A$2,4),"d") = 0,"TODAY!!!", IF(DATEDIF(TEXT(TODAY(),"dd/mm/yyyy"),TEXT(B15,"dd/mm/")&RIGHT(A$2,4),"d") > 0, DATEDIF(TEXT(TODAY(),"dd/mm/yyyy"), TEXT(B15,"dd/mm/")&RIGHT(A$2,4),"d")&" Days to go!",""))),"") | P15: Valentines | Q15: 14th | R15: 50 | U15: =R15-T15 -> 50
A16: Alfie | B16: 45691 | E16: =DATEDIF(B16,NOW(),"y") -> 1 | F16: 20
A17: Jordan | B17: 34368 | C17: =TEXT(B17,"MMDD") -> 0203 | E17: =DATEDIF(B17,NOW(),"y") -> 32 | F17: 0 | H17: Y | I17: 25.99 | J17: =IF(N17="MISSED",F17,F17-I17) -> -25.99 | N17: =IF(TEXT(TODAY(),"YYYY")=RIGHT(A$2,4), IF(ISERROR(DATEDIF(TEXT(TODAY(),"dd/mm/yyyy"),TEXT(B17,"dd/mm/")&RIGHT(A$2,4),"d")),IF(H17="Y","DONE","MISSED"), IF(DATEDIF(TEXT(TODAY(),"dd/mm/yyyy"),TEXT(B17,"dd/mm/")&RIGHT(A$2,4),"d") = 0,"TODAY!!!", IF(DATEDIF(TEXT(TODAY(),"dd/mm/yyyy"),TEXT(B17,"dd/mm/")&RIGHT(A$2,4),"d") > 0, DATEDIF(TEXT(TODAY(),"dd/mm/yyyy"), TEXT(B17,"dd/mm/")&RIGHT(A$2,4),"d")&" Days to go!",""))),"")
A18: Auntie Jo | B18: 42404 | C18: =TEXT(B18,"MMDD") -> 0204 | E18: =DATEDIF(B18,NOW(),"y") -> 10 | F18: 0 | J18: =IF(N18="MISSED",F18,F18-I18) -> 0 | N18: =IF(TEXT(TODAY(),"YYYY")=RIGHT(A$2,4), IF(ISERROR(DATEDIF(TEXT(TODAY(),"dd/mm/yyyy"),TEXT(B18,"dd/mm/")&RIGHT(A$2,4),"d")),IF(H18="Y","DONE","MISSED"), IF(DATEDIF(TEXT(TODAY(),"dd/mm/yyyy"),TEXT(B18,"dd/mm/")&RIGHT(A$2,4),"d") = 0,"TODAY!!!", IF(DATEDIF(TEXT(TODAY(),"dd/mm/yyyy"),TEXT(B18,"dd/mm/")&RIGHT(A$2,4),"d") > 0, DATEDIF(TEXT(TODAY(),"dd/mm/yyyy"), TEXT(B18,"dd/mm/")&RIGHT(A$2,4),"d")&" Days to go!",""))),"")
A19: William | B19: 40215 | C19: =TEXT(B19,"MMDD") -> 0206 | E19: =DATEDIF(B19,NOW(),"y") -> 16 | F19: 10 | G19: Cash | H19: Y | I19: 10 | J19: =IF(N19="MISSED",F19,F19-I19) -> 0 | N19: =IF(TEXT(TODAY(),"YYYY")=RIGHT(A$2,4), IF(ISERROR(DATEDIF(TEXT(TODAY(),"dd/mm/yyyy"),TEXT(B19,"dd/mm/")&RIGHT(A$2,4),"d")),IF(H19="Y","DONE","MISSED"), IF(DATEDIF(TEXT(TODAY(),"dd/mm/yyyy"),TEXT(B19,"dd/mm/")&RIGHT(A$2,4),"d") = 0,"TODAY!!!", IF(DATEDIF(TEXT(TODAY(),"dd/mm/yyyy"),TEXT(B19,"dd/mm/")&RIGHT(A$2,4),"d") > 0, DATEDIF(TEXT(TODAY(),"dd/mm/yyyy"), TEXT(B19,"dd/mm/")&RIGHT(A$2,4),"d")&" Days to go!",""))),"")
P20: =275+250 -> 525
A21: MAR | B21: =SUM(F22:F30) -> 105 | J21: =SUM(J22:J30) -> 80 | K21: =SUM(B21,R21) -> 305 | L21: =L14+(($F$105/12)-B21-R21) -> 180 | M21: =IF(N21<>"",N21,(M14+($F$105/12))-B21-R21+(J21+U21)) -> 664.44 | P21: MAR | R21: =SUM(R24:R28) -> 200 | U21: =SUM(U24:U28) -> 200
A22: Inesa | B22: 27829 | E22: =DATEDIF(B22,NOW(),"y") -> 50 | F22: 0 | H22: Y | J22: =IF(N22="MISSED",F22,F22-I22) -> 0 | N22: =IF(TEXT(TODAY(),"YYYY")=RIGHT(A$2,4), IF(ISERROR(DATEDIF(TEXT(TODAY(),"dd/mm/yyyy"),TEXT(B22,"dd/mm/")&RIGHT(A$2,4),"d")),IF(H22="Y","DONE","MISSED"), IF(DATEDIF(TEXT(TODAY(),"dd/mm/yyyy"),TEXT(B22,"dd/mm/")&RIGHT(A$2,4),"d") = 0,"TODAY!!!", IF(DATEDIF(TEXT(TODAY(),"dd/mm/yyyy"),TEXT(B22,"dd/mm/")&RIGHT(A$2,4),"d") > 0, DATEDIF(TEXT(TODAY(),"dd/mm/yyyy"), TEXT(B22,"dd/mm/")&RIGHT(A$2,4),"d")&" Days to go!",""))),"")
A23: Babu | F23: 40 | H23: Y | J23: =IF(N23="MISSED",F23,F23-I23) -> 40
A24: Lea | B24: 37694 | C24: =TEXT(B24,"MMDD") -> 0314 | E24: =DATEDIF(B24,NOW(),"y") -> 23 | F24: 0 | G24: Cash | H24: Y | J24: =IF(N24="MISSED",F24,F24-I24) -> 0 | N24: =IF(TEXT(TODAY(),"YYYY")=RIGHT(A$2,4), IF(ISERROR(DATEDIF(TEXT(TODAY(),"dd/mm/yyyy"),TEXT(B24,"dd/mm/")&RIGHT(A$2,4),"d")),IF(H24="Y","DONE","MISSED"), IF(DATEDIF(TEXT(TODAY(),"dd/mm/yyyy"),TEXT(B24,"dd/mm/")&RIGHT(A$2,4),"d") = 0,"TODAY!!!", IF(DATEDIF(TEXT(TODAY(),"dd/mm/yyyy"),TEXT(B24,"dd/mm/")&RIGHT(A$2,4),"d") > 0, DATEDIF(TEXT(TODAY(),"dd/mm/yyyy"), TEXT(B24,"dd/mm/")&RIGHT(A$2,4),"d")&" Days to go!",""))),"") | P24: Womens Day | Q24: 8th | R24: 100 | S24: Flowers (kris, mum, inessa) | U24: =R24-T24 -> 100
A25: Morgan | B25: 37694 | C25: =TEXT(B25,"MMDD") -> 0314 | E25: =DATEDIF(B25,NOW(),"y") -> 23 | F25: 0 | G25: Cash | H25: Y | J25: =IF(N25="MISSED",F25,F25-I25) -> 0 | N25: =IF(TEXT(TODAY(),"YYYY")=RIGHT(A$2,4), IF(ISERROR(DATEDIF(TEXT(TODAY(),"dd/mm/yyyy"),TEXT(B25,"dd/mm/")&RIGHT(A$2,4),"d")),IF(H25="Y","DONE","MISSED"), IF(DATEDIF(TEXT(TODAY(),"dd/mm/yyyy"),TEXT(B25,"dd/mm/")&RIGHT(A$2,4),"d") = 0,"TODAY!!!", IF(DATEDIF(TEXT(TODAY(),"dd/mm/yyyy"),TEXT(B25,"dd/mm/")&RIGHT(A$2,4),"d") > 0, DATEDIF(TEXT(TODAY(),"dd/mm/yyyy"), TEXT(B25,"dd/mm/")&RIGHT(A$2,4),"d")&" Days to go!",""))),"") | P25: Mothers Day | Q25: 27th | R25: 100 | S25: Day out | U25: =R25-T25 -> 100
A26: Dave | B26: 35145 | C26: =TEXT(B26,"MMDD") -> 0321 | E26: =DATEDIF(B26,NOW(),"y") -> 30 | F26: 0 | J26: =IF(N26="MISSED",F26,F26-I26) -> 0 | N26: =IF(TEXT(TODAY(),"YYYY")=RIGHT(A$2,4), IF(ISERROR(DATEDIF(TEXT(TODAY(),"dd/mm/yyyy"),TEXT(B26,"dd/mm/")&RIGHT(A$2,4),"d")),IF(H26="Y","DONE","MISSED"), IF(DATEDIF(TEXT(TODAY(),"dd/mm/yyyy"),TEXT(B26,"dd/mm/")&RIGHT(A$2,4),"d") = 0,"TODAY!!!", IF(DATEDIF(TEXT(TODAY(),"dd/mm/yyyy"),TEXT(B26,"dd/mm/")&RIGHT(A$2,4),"d") > 0, DATEDIF(TEXT(TODAY(),"dd/mm/yyyy"), TEXT(B26,"dd/mm/")&RIGHT(A$2,4),"d")&" Days to go!",""))),"")
A27: Auntie Jean (RIP) | B27: 42453 | C27: =TEXT(B27,"MMDD") -> 0324 | D27: ?? | E27: =DATEDIF(B27,NOW(),"y") -> 10 | F27: 0 | J27: =IF(N27="MISSED",F27,F27-I27) -> 0 | N27: =IF(TEXT(TODAY(),"YYYY")=RIGHT(A$2,4), IF(ISERROR(DATEDIF(TEXT(TODAY(),"dd/mm/yyyy"),TEXT(B27,"dd/mm/")&RIGHT(A$2,4),"d")),IF(H27="Y","DONE","MISSED"), IF(DATEDIF(TEXT(TODAY(),"dd/mm/yyyy"),TEXT(B27,"dd/mm/")&RIGHT(A$2,4),"d") = 0,"TODAY!!!", IF(DATEDIF(TEXT(TODAY(),"dd/mm/yyyy"),TEXT(B27,"dd/mm/")&RIGHT(A$2,4),"d") > 0, DATEDIF(TEXT(TODAY(),"dd/mm/yyyy"), TEXT(B27,"dd/mm/")&RIGHT(A$2,4),"d")&" Days to go!",""))),"")
A28: Uncle Chris | B28: 42458 | C28: =TEXT(B28,"MMDD") -> 0329 | E28: =DATEDIF(B28,NOW(),"y") -> 10 | F28: 0 | J28: =IF(N28="MISSED",F28,F28-I28) -> 0 | N28: =IF(TEXT(TODAY(),"YYYY")=RIGHT(A$2,4), IF(ISERROR(DATEDIF(TEXT(TODAY(),"dd/mm/yyyy"),TEXT(B28,"dd/mm/")&RIGHT(A$2,4),"d")),IF(H28="Y","DONE","MISSED"), IF(DATEDIF(TEXT(TODAY(),"dd/mm/yyyy"),TEXT(B28,"dd/mm/")&RIGHT(A$2,4),"d") = 0,"TODAY!!!", IF(DATEDIF(TEXT(TODAY(),"dd/mm/yyyy"),TEXT(B28,"dd/mm/")&RIGHT(A$2,4),"d") > 0, DATEDIF(TEXT(TODAY(),"dd/mm/yyyy"), TEXT(B28,"dd/mm/")&RIGHT(A$2,4),"d")&" Days to go!",""))),"")
A29: Hugo | B29: 42823 | E29: =DATEDIF(B29,NOW(),"y") -> 9 | F29: 25
A30: Tania | B30: 20545 | C30: =TEXT(B30,"MMDD") -> 0331 | E30: =DATEDIF(B30,NOW(),"y") -> 70 | F30: 40 | H30: Y | J30: =IF(N30="MISSED",F30,F30-I30) -> 40 | N30: =IF(TEXT(TODAY(),"YYYY")=RIGHT(A$2,4), IF(ISERROR(DATEDIF(TEXT(TODAY(),"dd/mm/yyyy"),TEXT(B30,"dd/mm/")&RIGHT(A$2,4),"d")),IF(H30="Y","DONE","MISSED"), IF(DATEDIF(TEXT(TODAY(),"dd/mm/yyyy"),TEXT(B30,"dd/mm/")&RIGHT(A$2,4),"d") = 0,"TODAY!!!", IF(DATEDIF(TEXT(TODAY(),"dd/mm/yyyy"),TEXT(B30,"dd/mm/")&RIGHT(A$2,4),"d") > 0, DATEDIF(TEXT(TODAY(),"dd/mm/yyyy"), TEXT(B30,"dd/mm/")&RIGHT(A$2,4),"d")&" Days to go!",""))),"")
A32: APR | B32: =SUM(F33:F35) -> 50 | J32: =SUM(J33:J35) -> 50 | K32: =SUM(B32,R32) -> 100 | L32: =L21+(($F$105/12))-B32-R32 -> 315 | M32: =IF(N32<>"",N32,(M21+($F$105/12))-B32-R32+(J32+U32)) -> 79 | N32: 79 | P32: APR | R32: =SUM(R33:R35) -> 50 | U32: =SUM(U33:U35) -> 50
A33: Dad | B33: 18733 | C33: =TEXT(B33,"MMDD") -> 0415 | E33: =DATEDIF(B33,NOW(),"y") -> 75 | F33: 50 | H33: Y | J33: =IF(N33="MISSED",F33,F33-I33) -> 50 | N33: =IF(TEXT(TODAY(),"YYYY")=RIGHT(A$2,4), IF(ISERROR(DATEDIF(TEXT(TODAY(),"dd/mm/yyyy"),TEXT(B33,"dd/mm/")&RIGHT(A$2,4),"d")),IF(H33="Y","DONE","MISSED"), IF(DATEDIF(TEXT(TODAY(),"dd/mm/yyyy"),TEXT(B33,"dd/mm/")&RIGHT(A$2,4),"d") = 0,"TODAY!!!", IF(DATEDIF(TEXT(TODAY(),"dd/mm/yyyy"),TEXT(B33,"dd/mm/")&RIGHT(A$2,4),"d") > 0, DATEDIF(TEXT(TODAY(),"dd/mm/yyyy"), TEXT(B33,"dd/mm/")&RIGHT(A$2,4),"d")&" Days to go!",""))),"") | P33: Mum + Dad Anv | Q33: 1st | R33: 50 | S33: Dinner | U33: =R33-T33 -> 50
A34: Sarah | B34: 34074 | E34: =DATEDIF(B34,NOW(),"y") -> 33 | F34: 0 | J34: =IF(N34="MISSED",F34,F34-I34) -> 0
A35: Grandad (RIP) | B35: 12162 | C35: =TEXT(B35,"MMDD") -> 0418 | D35: ?? | E35: =DATEDIF(B35,NOW(),"y") -> 93 | F35: 0 | J35: =IF(N35="MISSED",F35,F35-I35) -> 0 | N35: =IF(TEXT(TODAY(),"YYYY")=RIGHT(A$2,4), IF(ISERROR(DATEDIF(TEXT(TODAY(),"dd/mm/yyyy"),TEXT(B35,"dd/mm/")&RIGHT(A$2,4),"d")),IF(H35="Y","DONE","MISSED"), IF(DATEDIF(TEXT(TODAY(),"dd/mm/yyyy"),TEXT(B35,"dd/mm/")&RIGHT(A$2,4),"d") = 0,"TODAY!!!", IF(DATEDIF(TEXT(TODAY(),"dd/mm/yyyy"),TEXT(B35,"dd/mm/")&RIGHT(A$2,4),"d") > 0, DATEDIF(TEXT(TODAY(),"dd/mm/yyyy"), TEXT(B35,"dd/mm/")&RIGHT(A$2,4),"d")&" Days to go!",""))),"")
A37: MAY | B37: =SUM(F38:F45) -> 25 | J37: =SUM(J38:J45) -> 0 | K37: =SUM(B37,R37) -> 125 | L37: =L32+($F$105/12)-B37-R37 -> 425 | M37: =IF(N37<>"",N37,(M32+($F$105/12))-B37-R37+(J37+U37)+13) -> 202 | P37: MAY | R37: =SUM(R38:R45) -> 100 | U37: =SUM(U38:U45) -> 0
A38: Brother Andrew | B38: 42495 | C38: =TEXT(B38,"MMDD") -> 0505 | E38: =DATEDIF(B38,NOW(),"y") -> 10 | F38: 0 | J38: =IF(N38="MISSED",F38,F38-I38) -> 0 | N38: =IF(TEXT(TODAY(),"YYYY")=RIGHT(A$2,4), IF(ISERROR(DATEDIF(TEXT(TODAY(),"dd/mm/yyyy"),TEXT(B38,"dd/mm/")&RIGHT(A$2,4),"d")),IF(H38="Y","DONE","MISSED"), IF(DATEDIF(TEXT(TODAY(),"dd/mm/yyyy"),TEXT(B38,"dd/mm/")&RIGHT(A$2,4),"d") = 0,"TODAY!!!", IF(DATEDIF(TEXT(TODAY(),"dd/mm/yyyy"),TEXT(B38,"dd/mm/")&RIGHT(A$2,4),"d") > 0, DATEDIF(TEXT(TODAY(),"dd/mm/yyyy"), TEXT(B38,"dd/mm/")&RIGHT(A$2,4),"d")&" Days to go!",""))),"") | P38: Anniversary | Q38: 17 | R38: 100 | S38: Dinner
A39: Christian | B39: 33730 | C39: =TEXT(B39,"MMDD") -> 0506 | E39: =DATEDIF(B39,NOW(),"y") -> 34 | F39: 0 | J39: =IF(N39="MISSED",F39,F39-I39) -> 0 | N39: =IF(TEXT(TODAY(),"YYYY")=RIGHT(A$2,4), IF(ISERROR(DATEDIF(TEXT(TODAY(),"dd/mm/yyyy"),TEXT(B39,"dd/mm/")&RIGHT(A$2,4),"d")),IF(H39="Y","DONE","MISSED"), IF(DATEDIF(TEXT(TODAY(),"dd/mm/yyyy"),TEXT(B39,"dd/mm/")&RIGHT(A$2,4),"d") = 0,"TODAY!!!", IF(DATEDIF(TEXT(TODAY(),"dd/mm/yyyy"),TEXT(B39,"dd/mm/")&RIGHT(A$2,4),"d") > 0, DATEDIF(TEXT(TODAY(),"dd/mm/yyyy"), TEXT(B39,"dd/mm/")&RIGHT(A$2,4),"d")&" Days to go!",""))),"")
A40: Brother Lee | B40: 27895 | C40: =TEXT(B40,"MMDD") -> 0515 | E40: =DATEDIF(B40,NOW(),"y") -> 50 | F40: 0 | J40: =IF(N40="MISSED",F40,F40-I40) -> 0 | N40: =IF(TEXT(TODAY(),"YYYY")=RIGHT(A$2,4), IF(ISERROR(DATEDIF(TEXT(TODAY(),"dd/mm/yyyy"),TEXT(B40,"dd/mm/")&RIGHT(A$2,4),"d")),IF(H40="Y","DONE","MISSED"), IF(DATEDIF(TEXT(TODAY(),"dd/mm/yyyy"),TEXT(B40,"dd/mm/")&RIGHT(A$2,4),"d") = 0,"TODAY!!!", IF(DATEDIF(TEXT(TODAY(),"dd/mm/yyyy"),TEXT(B40,"dd/mm/")&RIGHT(A$2,4),"d") > 0, DATEDIF(TEXT(TODAY(),"dd/mm/yyyy"), TEXT(B40,"dd/mm/")&RIGHT(A$2,4),"d")&" Days to go!",""))),"")
A41: Brother Craig | B41: 27895 | C41: =TEXT(B41,"MMDD") -> 0515 | E41: =DATEDIF(B41,NOW(),"y") -> 50 | F41: 0 | J41: =IF(N41="MISSED",F41,F41-I41) -> 0 | N41: =IF(TEXT(TODAY(),"YYYY")=RIGHT(A$2,4), IF(ISERROR(DATEDIF(TEXT(TODAY(),"dd/mm/yyyy"),TEXT(B41,"dd/mm/")&RIGHT(A$2,4),"d")),IF(H41="Y","DONE","MISSED"), IF(DATEDIF(TEXT(TODAY(),"dd/mm/yyyy"),TEXT(B41,"dd/mm/")&RIGHT(A$2,4),"d") = 0,"TODAY!!!", IF(DATEDIF(TEXT(TODAY(),"dd/mm/yyyy"),TEXT(B41,"dd/mm/")&RIGHT(A$2,4),"d") > 0, DATEDIF(TEXT(TODAY(),"dd/mm/yyyy"), TEXT(B41,"dd/mm/")&RIGHT(A$2,4),"d")&" Days to go!",""))),"")
A42: Dax | B42: 43236 | E42: =DATEDIF(B42,NOW(),"y") -> 8 | F42: 25
A43: Uncle Mick (RIP) | B43: 16942 | C43: =TEXT(B43,"MMDD") -> 0520 | E43: =DATEDIF(B43,NOW(),"y") -> 80 | F43: 0 | J43: =IF(N43="MISSED",F43,F43-I43) -> 0 | N43: =IF(TEXT(TODAY(),"YYYY")=RIGHT(A$2,4), IF(ISERROR(DATEDIF(TEXT(TODAY(),"dd/mm/yyyy"),TEXT(B43,"dd/mm/")&RIGHT(A$2,4),"d")),IF(H43="Y","DONE","MISSED"), IF(DATEDIF(TEXT(TODAY(),"dd/mm/yyyy"),TEXT(B43,"dd/mm/")&RIGHT(A$2,4),"d") = 0,"TODAY!!!", IF(DATEDIF(TEXT(TODAY(),"dd/mm/yyyy"),TEXT(B43,"dd/mm/")&RIGHT(A$2,4),"d") > 0, DATEDIF(TEXT(TODAY(),"dd/mm/yyyy"), TEXT(B43,"dd/mm/")&RIGHT(A$2,4),"d")&" Days to go!",""))),"")
...

Sheet 5 week template
A1: MONTH | B1: Monthly Allowance | C1: ="22/02/17" & " - " & "28/02/17" -> 22/02/17 - 28/02/17 | D1: =TEXT(DATEVALUE(RIGHT(C1,8))+1,"dd/mm/yy")& " - "& TEXT(DATEVALUE(RIGHT(C1,8))+7,"dd/mm/yy") -> 01/03/17 - 07/03/17 | E1: =TEXT(DATEVALUE(RIGHT(D1,8))+1,"dd/mm/yy")& " - "& TEXT(DATEVALUE(RIGHT(D1,8))+7,"dd/mm/yy") -> 08/03/17 - 14/03/17 | F1: =TEXT(DATEVALUE(RIGHT(E1,8))+1,"dd/mm/yy")& " - "& TEXT(DATEVALUE(RIGHT(E1,8))+7,"dd/mm/yy") -> 15/03/17 - 21/03/17 | G1: =TEXT(DATEVALUE(RIGHT(F1,8))+1,"dd/mm/yy")& " - "& TEXT(DATEVALUE(RIGHT(F1,8))+7,"dd/mm/yy") -> 22/03/17 - 28/03/17 | H1: Remaining
A2: Outgoings | C2: =SUM(C5:C20) -> 0 | D2: =SUM(D5:D20) -> 0 | E2: =SUM(E5:E20) -> 0 | F2: =SUM(F5:F20) -> 0 | G2: =SUM(G5:G20) -> 0
A4: General | B4: =SUM(B5:B9) -> 460 | H4: ="Remaining: £" & SUM(H5:H9) -> Remaining: £460
A5: Car Petrol | B5: =IF(G1="Remaining",17.5*4,17.5*5) -> 87.5 | H5: =IF(B5<>"",B5-C5-D5-E5-F5-G5,"") -> 87.5 | I5: =A5 -> Car Petrol
A6: Bike petrol | B6: =IF(G1="Remaining",4.5*4,4.5*5) -> 22.5 | H6: =IF(B6<>"",B6-C6-D6-E6-F6-G6,"") -> 22.5 | I6: =A6 -> Bike petrol
A7: Food | B7: =IF(G1="Remaining",30*4,IF(H1= "Remaining",30* 5,"")) -> 150 | H7: =IF(B7<>"",B7-C7-D7-E7-F7-G7,"") -> 150 | I7: =A7 -> Food
A8: Gift Fund | B8: 100 | H8: =IF(B8<>"",B8-C8-D8-E8-F8-G8,"") -> 100 | I8: =A8 -> Gift Fund
A9: Holiday Fund | B9: =IF(G1="Remaining",20*4,IF(H1= "Remaining",20* 5,"")) -> 100 | H9: =IF(B9<>"",B9-C9-D9-E9-F9-G9,"") -> 100 | I9: =A9 -> Holiday Fund
A10: Misc | B10: =IF(B26 <> 0,B26-SUM(B5:B9)-B12-B24,0) -> -16.26 | H10: =IF(B10<>"",B10-C10-D10-E10-F10-G10,"") -> -16.26 | I10: Misc
A12: Direct Debits | B12: =SUM(B13:B21) -> 859.87 | H12: ="Remaining: £" & SUM(H13:H21) -> Remaining: £859.87
A13: House | B13: 500 | H13: =IF(B13<>"",B13-C13-D13-E13-F13-G13,"") -> 500 | I13: =A13 -> House
A14: Ring | B14: 104.92 | H14: =IF(B14<>"",B14-C14-D14-E14-F14-G14,"") -> 104.92 | I14: =A14 -> Ring
A15: Phone | B15: ='Joint Outgoings'!C29 -> 16.99 | H15: =IF(B15<>"",B15-C15-D15-E15-F15-G15,"") -> 16.99 | I15: =A15 -> Phone
A16: Gym | B16: 17.99 | H16: =IF(B16<>"",B16-C16-D16-E16-F16-G16,"") -> 17.99 | I16: =A16 -> Gym
A17: Car v.tax | B17: ='Joint Outgoings'!C25 -> 200 | H17: =IF(B17<>"",B17-C17-D17-E17-F17-G17,"") -> 200 | I17: =A17 -> Car v.tax
A18: Sky Movies | B18: 3.99 | H18: =IF(B18<>"",B18-C18-D18-E18-F18-G18,"") -> 3.99 | I18: =A18 -> Sky Movies
A19: Spotify | B19: 0 | H19: =IF(B19<>"",B19-C19-D19-E19-F19-G19,"") -> 0 | I19: =A19 -> Spotify
A20: Onedrive | B20: 7.99 | H20: =IF(B20<>"",B20-C20-D20-E20-F20-G20,"") -> 7.99 | I20: =A20 -> Onedrive
A21: Amazon Prime | B21: 7.99 | H21: =IF(B21<>"",B21-C21-D21-E21-F21-G21,"") -> 7.99 | I21: =A21 -> Amazon Prime
A23: Savings
A24: Savings In | B24: =IF(SUM(C24:G24)<>0,SUM(C24:G24),0) -> 0
A25: Savings Out | B25: =IF(SUM(C25:G25)<>0,SUM(C25:G25),0) -> 0
A26: Income | B26: =SUM(C26:G26) -> 1303.61 | C26: 1303.61 | H26: =SUM(H5:H25) & " / " & B26 -> 1303.61 / 1303.61
A27: Reminders: | B27: =IF(MONTH(TODAY()) = 11, IF(MONTH(A1(RIGHT,3)) = 11, "Bike insurance due",""),"")
B28: =IF(MONTH(TODAY()) = 6, IF(MONTH(A1(RIGHT,3)) = 6, "Bike insurance due",""),"") | H28: =SUM(H5:H25)*12 -> 15643.32
A31: Pay after del:

Sheet 4 week template
A1: MONTH | B1: Monthly Allowance | C1: ="29/06/16" & " - " & "05/7/16" -> 29/06/16 - 05/7/16 | D1: =TEXT(DATEVALUE(RIGHT(C1,8))+1,"dd/mm/yy")& " - "& TEXT(DATEVALUE(RIGHT(C1,8))+7,"dd/mm/yy") -> 06/07/16 - 12/07/16 | E1: =TEXT(DATEVALUE(RIGHT(D1,8))+1,"dd/mm/yy")& " - "& TEXT(DATEVALUE(RIGHT(D1,8))+7,"dd/mm/yy") -> 13/07/16 - 19/07/16 | F1: =TEXT(DATEVALUE(RIGHT(E1,8))+1,"dd/mm/yy")& " - "& TEXT(DATEVALUE(RIGHT(E1,8))+7,"dd/mm/yy") -> 20/07/16 - 26/07/16 | G1: Remaining
A2: Outgoings | C2: =SUM(C5:C20) -> 0 | D2: =SUM(D5:D20) -> 0 | E2: =SUM(E5:E20) -> 0 | F2: =SUM(F5:F20) -> 0
A4: General | B4: =SUM(B5:B9) -> 368 | G4: ="Remaining: £" & ROUND(SUM(G5:G10),2) -> Remaining: £443.74
A5: Car Petrol | B5: =IF(G1="Remaining",17.5*4,17.5*5) -> 70 | G5: =IF(B5<>"",B5-C5-D5-E5-F5,"") -> 70 | H5: =A5 -> Car Petrol
A6: Bike petrol | B6: =IF(G1="Remaining",4.5*4,4.5*5) -> 18 | G6: =IF(B6<>"",B6-C6-D6-E6-F6,"") -> 18 | H6: =A6 -> Bike petrol
A7: Food | B7: =IF(G1="Remaining",30*4,IF(H1= "Remaining",30* 5,"")) -> 120 | G7: =IF(B7<>"",B7-C7-D7-E7-F7,"") -> 120 | H7: =A7 -> Food
A8: Gift Fund | B8: =IF(G1="Remaining",20*4,IF(H1= "Remaining",20* 5,"")) -> 80 | G8: =IF(B8<>"",B8-C8-D8-E8-F8,"") -> 80 | H8: =A8 -> Gift Fund
A9: Holiday Fund | B9: =IF(G1="Remaining",20*4,IF(H1= "Remaining",20* 5,"")) -> 80 | G9: =IF(B9<>"",B9-C9-D9-E9-F9,"") -> 80 | H9: =A9 -> Holiday Fund
A10: Misc | B10: =IF(B26 <> 0,B26-B4-B12-B24,0) -> 75.74 | G10: =IF(B10<>"",B10-C10-D10-E10-F10,"") -> 75.74 | H10: Misc
A12: Direct debits | B12: =SUM(B13:B21) -> 859.87 | G12: ="Remaining: £" & ROUND(SUM(G13:G21),2) -> Remaining: £859.87
A13: House | B13: 500 | G13: =IF(B13<>"",B13-C13-D13-E13-F13,"") -> 500 | H13: =A13 -> House
A14: Ring | B14: 104.92 | G14: =IF(B14<>"",B14-C14-D14-E14-F14,"") -> 104.92 | H14: =A14 -> Ring
A15: Phone | B15: ='Joint Outgoings'!C29 -> 16.99 | G15: =IF(B15<>"",B15-C15-D15-E15-F15,"") -> 16.99 | H15: =A15 -> Phone
A16: Gym | B16: 17.99 | G16: =IF(B16<>"",B16-C16-D16-E16-F16,"") -> 17.99 | H16: =A16 -> Gym
A17: Car v.tax | B17: ='Joint Outgoings'!C25 -> 200 | G17: =IF(B17<>"",B17-C17-D17-E17-F17,"") -> 200 | H17: =A17 -> Car v.tax
A18: Sky Movies | B18: 3.99 | G18: =IF(B18<>"",B18-C18-D18-E18-F18,"") -> 3.99 | H18: =A18 -> Sky Movies
A19: Spotify | B19: 0 | G19: =IF(B19<>"",B19-C19-D19-E19-F19,"") -> 0 | H19: =A19 -> Spotify
A20: Onedrive | B20: 7.99 | G20: =IF(B20<>"",B20-C20-D20-E20-F20,"") -> 7.99 | H20: =A20 -> Onedrive
A21: Amazon Prime | B21: 7.99 | G21: =IF(B21<>"",B21-C21-D21-E21-F21,"") -> 7.99 | H21: =A21 -> Amazon Prime
A23: Savings
A24: Savings In | B24: =SUM(C24:F24) -> 0
A25: Savings Out | B25: =SUM(C25:F25) -> 0
A26: Income | B26: =SUM(C26:F26) -> 1303.61 | C26: 1303.61 | G26: =SUM(G5:G20) & " / " & B26 -> 1295.62 / 1303.61
G27: =IF(ROUND(SUM(G5:G20),2)>0,IF(ROUND(SUM(G5:G20),2)<ROUND(SUMIF(G5:G20,">0"),2),"NOT ENOUGH MONEY",""),"NO MONEY")
A28: Reminders: | B28: =IF(MONTH(TODAY()) = 11, IF(MONTH(A1(RIGHT,3)) = 11, "Bike insurance due",""),"")
B29: =IF(MONTH(TODAY()) = 6, IF(MONTH(A1(RIGHT,3)) = 6, "Bike insurance due",""),"")
A31: Pay after del:

Sheet Wages 2014
A1: 2014/Month | B1: Dates worked | C1: Days | D1: Hours | E1: Total Earned | F1: Total Bonus | G1: Pay + Bonus | H1: NI (12%) | I1: Pension (5%) | J1: Income Tax (%20) | K1: Expected | L1: Payday | M1: Total Paid (on date) | N1: Difference | O1: Total Late Payments | P1: Missing Paid On
A2: JAN | C2: =IF(B2<>"",((LEN(B2)-LEN(SUBSTITUTE(B2,",","")))/LEN(",")+1)+((LEN(B2)-LEN(SUBSTITUTE(B2,"/","")))/LEN("/")/2)- ((LEN(B2)-LEN(SUBSTITUTE(B2,"/","")))/LEN("/")),0) -> 0 | D2: =ROUND((((C2*7.5)/9)+(C2*7.5)), 2) -> 0 | E2: =D2*B15 -> 0 | F2: =IF(B$16<>0,B$16*D2-E2,0) -> 0 | G2: =IF(B16<>0,IF(ISREF(INDIRECT("'"&"Wages "&LEFT(A1,4)-1&"'!A1"))=TRUE,INDIRECT(CONCATENATE("'Wages ",LEFT(A1,4)-1,"'!F11")) + INDIRECT(CONCATENATE("'Wages ",LEFT(A1,4)-1,"'!F12")) + INDIRECT(CONCATENATE("'Wages ",LEFT(A1,4)-1,"'!F13")),""),0) -> 0 | H2: =IF(G2="",IF((((E2-I2)/4)-155)>0,((((E2-I2)/4)-155)*0.12)*4,0),IF((((G2-I2)/4)-155)>0,((((G2-I2)/4)-155)*0.12)*4,0)) -> 0 | I2: =IF(B$17<>"N",IF(G2="",E2*0.05,G2*0.05),0) -> 0 | J2: =IF(E2>11000,E2-11000*0.2,0) -> 0 | K2: =IF(G2="",E2-H2-I2-J2,G2-H2-I2-J2) -> 0 | L2: =TEXT(DATE(LEFT(A$1,4),IF(MONTH(DATEVALUE(A2&" 1"))+1>12,1,MONTH(DATEVALUE(A2&" 1"))+1),1),"mmm")&" " &DAY(EOMONTH((DATE(LEFT(A$1,4),MONTH(DATEVALUE(A2&" 1"))+1,1)),0)+1-WEEKDAY(EOMONTH((DATE(LEFT(A$1,4),MONTH(DATEVALUE(A2&" 1"))+1,1)),0)+1-4)) -> Feb 26
A3: FEB | C3: =IF(B3<>"",((LEN(B3)-LEN(SUBSTITUTE(B3,",","")))/LEN(",")+1)+((LEN(B3)-LEN(SUBSTITUTE(B3,"/","")))/LEN("/")/2)- ((LEN(B3)-LEN(SUBSTITUTE(B3,"/","")))/LEN("/")),0) -> 0 | D3: =ROUND((((C3*7.5)/9)+(C3*7.5)), 2) -> 0 | E3: =D3*B15 -> 0 | F3: =IF(B$16<>0,B$16*D3-E3,0) -> 0 | H3: =IF(G3="",IF((((E3-I3)/4)-155)>0,((((E3-I3)/4)-155)*0.12)*4,0),IF((((G3-I3)/4)-155)>0,((((G3-I3)/4)-155)*0.12)*4,0)) -> 0 | I3: =IF(B$17<>"N",IF(G3="",E3*0.05,G3*0.05),0) -> 0 | J3: =IF(SUM(E$2:E3)>11000,E3-11000*0.2,0) -> 0 | K3: =IF(G3="",E3-H3-I3-J3,G3-H3-I3-J3) -> 0 | L3: =TEXT(DATE(LEFT(A$1,4),IF(MONTH(DATEVALUE(A3&" 1"))+1>12,1,MONTH(DATEVALUE(A3&" 1"))+1),1),"mmm")&" " &DAY(EOMONTH((DATE(LEFT(A$1,4),MONTH(DATEVALUE(A3&" 1"))+1,1)),0)+1-WEEKDAY(EOMONTH((DATE(LEFT(A$1,4),MONTH(DATEVALUE(A3&" 1"))+1,1)),0)+1-4)) -> Mar 26
A4: MAR | C4: =IF(B4<>"",((LEN(B4)-LEN(SUBSTITUTE(B4,",","")))/LEN(",")+1)+((LEN(B4)-LEN(SUBSTITUTE(B4,"/","")))/LEN("/")/2)- ((LEN(B4)-LEN(SUBSTITUTE(B4,"/","")))/LEN("/")),0) -> 0 | D4: =ROUND((((C4*7.5)/9)+(C4*7.5)), 2) -> 0 | E4: =D4*B15 -> 0 | F4: =IF(B$16<>0,B$16*D4-E4,0) -> 0 | H4: =IF(G4="",IF((((E4-I4)/4)-155)>0,((((E4-I4)/4)-155)*0.12)*4,0),IF((((G4-I4)/4)-155)>0,((((G4-I4)/4)-155)*0.12)*4,0)) -> 0 | I4: =IF(B$17<>"N",IF(G4="",E4*0.05,G4*0.05),0) -> 0 | J4: =IF(SUM(E$2:E4)>11000,E4-11000*0.2,0) -> 0 | K4: =IF(G4="",E4-H4-I4-J4,G4-H4-I4-J4) -> 0 | L4: =TEXT(DATE(LEFT(A$1,4),IF(MONTH(DATEVALUE(A4&" 1"))+1>12,1,MONTH(DATEVALUE(A4&" 1"))+1),1),"mmm")&" " &DAY(EOMONTH((DATE(LEFT(A$1,4),MONTH(DATEVALUE(A4&" 1"))+1,1)),0)+1-WEEKDAY(EOMONTH((DATE(LEFT(A$1,4),MONTH(DATEVALUE(A4&" 1"))+1,1)),0)+1-4)) -> Apr 30
A5: APR | C5: =IF(B5<>"",((LEN(B5)-LEN(SUBSTITUTE(B5,",","")))/LEN(",")+1)+((LEN(B5)-LEN(SUBSTITUTE(B5,"/","")))/LEN("/")/2)- ((LEN(B5)-LEN(SUBSTITUTE(B5,"/","")))/LEN("/")),0) -> 0 | D5: =ROUND((((C5*7.5)/9)+(C5*7.5)), 2) -> 0 | E5: =D5*B15 -> 0 | F5: =IF(B$16<>0,B$16*D5-E5,0) -> 0 | G5: =IF(B16<>0,E5+SUM(F2:F4),0) -> 0 | H5: =IF(G5="",IF((((E5-I5)/4)-155)>0,((((E5-I5)/4)-155)*0.12)*4,0),IF((((G5-I5)/4)-155)>0,((((G5-I5)/4)-155)*0.12)*4,0)) -> 0 | I5: =IF(B$17<>"N",IF(G5="",E5*0.05,G5*0.05),0) -> 0 | J5: =IF(SUM(E$2:E5)>11000,E5-11000*0.2,0) -> 0 | K5: =IF(G5="",E5-H5-I5-J5,G5-H5-I5-J5) -> 0 | L5: =TEXT(DATE(LEFT(A$1,4),IF(MONTH(DATEVALUE(A5&" 1"))+1>12,1,MONTH(DATEVALUE(A5&" 1"))+1),1),"mmm")&" " &DAY(EOMONTH((DATE(LEFT(A$1,4),MONTH(DATEVALUE(A5&" 1"))+1,1)),0)+1-WEEKDAY(EOMONTH((DATE(LEFT(A$1,4),MONTH(DATEVALUE(A5&" 1"))+1,1)),0)+1-4)) -> May 28
A6: MAY | B6: 12,13,14,15,16,19,20,21,22,23,27,28,29,30 | C6: =IF(B6<>"",((LEN(B6)-LEN(SUBSTITUTE(B6,",","")))/LEN(",")+1)+((LEN(B6)-LEN(SUBSTITUTE(B6,"/","")))/LEN("/")/2)- ((LEN(B6)-LEN(SUBSTITUTE(B6,"/","")))/LEN("/")),0) -> 14 | D6: =ROUND((((C6*7.5)/9)+(C6*7.5)), 2)+6.33+0.89 -> 123.89 | E6: =D6*B15 -> 905.66068 | F6: =IF(B$16<>0,B$16*D6-E6,0) -> 0 | H6: =IF(G6="",IF((((E6-I6)/4)-155)>0,((((E6-I6)/4)-155)*0.12)*4,0),IF((((G6-I6)/4)-155)>0,((((G6-I6)/4)-155)*0.12)*4,0)) -> 34.279281 | I6: =IF(B$17<>"N",IF(G6="",E6*0.05,G6*0.05),0) -> 0 | J6: =IF(SUM(E$2:E6)>11000,E6-11000*0.2,0) -> 0 | K6: =IF(G6="",E6-H6-I6-J6,G6-H6-I6-J6) -> 871.3814 | L6: =TEXT(DATE(LEFT(A$1,4),IF(MONTH(DATEVALUE(A6&" 1"))+1>12,1,MONTH(DATEVALUE(A6&" 1"))+1),1),"mmm")&" " &DAY(EOMONTH((DATE(LEFT(A$1,4),MONTH(DATEVALUE(A6&" 1"))+1,1)),0)+1-WEEKDAY(EOMONTH((DATE(LEFT(A$1,4),MONTH(DATEVALUE(A6&" 1"))+1,1)),0)+1-4)) -> Jun 25 | M6: 630 | N6: =K6-M6 -> 241.3814
A7: JUN | B7: 2,3,4,5,6,9,10,11,12,13,16,17,18,19,20,23,24,25,26,27 | C7: =IF(B7<>"",((LEN(B7)-LEN(SUBSTITUTE(B7,",","")))/LEN(",")+1)+((LEN(B7)-LEN(SUBSTITUTE(B7,"/","")))/LEN("/")/2)- ((LEN(B7)-LEN(SUBSTITUTE(B7,"/","")))/LEN("/")),0) -> 20 | D7: =ROUND((((C7*7.5)/9)+(C7*7.5)), 2) -> 166.67 | E7: =D7*B15 -> 1218.391 | F7: =IF(B$16<>0,B$16*D7-E7,0) -> 0 | H7: =IF(G7="",IF((((E7-I7)/4)-155)>0,((((E7-I7)/4)-155)*0.12)*4,0),IF((((G7-I7)/4)-155)>0,((((G7-I7)/4)-155)*0.12)*4,0)) -> 71.806924 | I7: =IF(B$17<>"N",IF(G7="",E7*0.05,G7*0.05),0) -> 0 | J7: =IF(SUM(E$2:E7)>11000,E7-11000*0.2,0) -> 0 | K7: =IF(G7="",E7-H7-I7-J7,G7-H7-I7-J7) -> 1146.5841 | L7: =TEXT(DATE(LEFT(A$1,4),IF(MONTH(DATEVALUE(A7&" 1"))+1>12,1,MONTH(DATEVALUE(A7&" 1"))+1),1),"mmm")&" " &DAY(EOMONTH((DATE(LEFT(A$1,4),MONTH(DATEVALUE(A7&" 1"))+1,1)),0)+1-WEEKDAY(EOMONTH((DATE(LEFT(A$1,4),MONTH(DATEVALUE(A7&" 1"))+1,1)),0)+1-4)) -> Jul 30 | M7: 915.53 | N7: =K7-M7 -> 231.05411 | O7: 400 | P7: 42671
A8: JUL | B8: 14,15,16,17,18,21,22,23,24,25,28,29,30,31,1 | C8: =IF(B8<>"",((LEN(B8)-LEN(SUBSTITUTE(B8,",","")))/LEN(",")+1)+((LEN(B8)-LEN(SUBSTITUTE(B8,"/","")))/LEN("/")/2)- ((LEN(B8)-LEN(SUBSTITUTE(B8,"/","")))/LEN("/")),0) -> 15 | D8: =ROUND((((C8*7.5)/9)+(C8*7.5)), 2)-0.83 -> 124.17 | E8: =D8*B15 -> 907.70753 | F8: =IF(B$16<>0,B$16*D8-E8,0) -> 0 | G8: =IF(B16<>0,E8+SUM(F5:F7),0) -> 0 | H8: =IF(G8="",IF((((E8-I8)/4)-155)>0,((((E8-I8)/4)-155)*0.12)*4,0),IF((((G8-I8)/4)-155)>0,((((G8-I8)/4)-155)*0.12)*4,0)) -> 0 | I8: =IF(B$17<>"N",IF(G8="",E8*0.05,G8*0.05),0) -> 0 | J8: =IF(SUM(E$2:E8)>11000,E8-11000*0.2,0) -> 0 | K8: =IF(G8="",E8-H8-I8-J8,G8-H8-I8-J8) -> 0 | L8: =TEXT(DATE(LEFT(A$1,4),IF(MONTH(DATEVALUE(A8&" 1"))+1>12,1,MONTH(DATEVALUE(A8&" 1"))+1),1),"mmm")&" " &DAY(EOMONTH((DATE(LEFT(A$1,4),MONTH(DATEVALUE(A8&" 1"))+1,1)),0)+1-WEEKDAY(EOMONTH((DATE(LEFT(A$1,4),MONTH(DATEVALUE(A8&" 1"))+1,1)),0)+1-4)) -> Aug 27 | M8: 714.26 | N8: =K8-M8 -> -714.26 | O8: 106.02 | P8: 42672
A9: AUG | B9: 5,6,7 | C9: =IF(B9<>"",((LEN(B9)-LEN(SUBSTITUTE(B9,",","")))/LEN(",")+1)+((LEN(B9)-LEN(SUBSTITUTE(B9,"/","")))/LEN("/")/2)- ((LEN(B9)-LEN(SUBSTITUTE(B9,"/","")))/LEN("/")),0) -> 3 | D9: =ROUND((((C9*7.5)/9)+(C9*7.5)), 2) -> 25 | E9: =D9*B15 -> 182.755 | F9: =IF(B$16<>0,B$16*D9-E9,0) -> 0 | H9: =IF(G9="",IF((((E9-I9)/4)-155)>0,((((E9-I9)/4)-155)*0.12)*4,0),IF((((G9-I9)/4)-155)>0,((((G9-I9)/4)-155)*0.12)*4,0)) -> 0 | I9: =IF(B$17<>"N",IF(G9="",E9*0.05,G9*0.05),0) -> 0 | J9: =IF(SUM(E$2:E9)>11000,E9-11000*0.2,0) -> 0 | K9: =IF(G9="",E9-H9-I9-J9,G9-H9-I9-J9) -> 182.755 | L9: =TEXT(DATE(LEFT(A$1,4),IF(MONTH(DATEVALUE(A9&" 1"))+1>12,1,MONTH(DATEVALUE(A9&" 1"))+1),1),"mmm")&" " &DAY(EOMONTH((DATE(LEFT(A$1,4),MONTH(DATEVALUE(A9&" 1"))+1,1)),0)+1-WEEKDAY(EOMONTH((DATE(LEFT(A$1,4),MONTH(DATEVALUE(A9&" 1"))+1,1)),0)+1-4)) -> Sep 24 | M9: 225.71 | O9: 170.96 | P9: 42700
A10: SEP | C10: =IF(B10<>"",((LEN(B10)-LEN(SUBSTITUTE(B10,",","")))/LEN(",")+1)+((LEN(B10)-LEN(SUBSTITUTE(B10,"/","")))/LEN("/")/2)- ((LEN(B10)-LEN(SUBSTITUTE(B10,"/","")))/LEN("/")),0) -> 0 | D10: =ROUND((((C10*7.5)/9)+(C10*7.5)), 2) -> 0 | E10: =D10*B15 -> 0 | F10: =IF(B$16<>0,B$16*D10-E10,0) -> 0 | H10: =IF(G10="",IF((((E10-I10)/4)-155)>0,((((E10-I10)/4)-155)*0.12)*4,0),IF((((G10-I10)/4)-155)>0,((((G10-I10)/4)-155)*0.12)*4,0)) -> 0 | I10: =IF(B$17<>"N",IF(G10="",E10*0.05,G10*0.05),0) -> 0 | J10: =IF(SUM(E$2:E10)>11000,E10-11000*0.2,0) -> 0 | K10: =IF(G10="",E10-H10-I10-J10,G10-H10-I10-J10) -> 0 | L10: =TEXT(DATE(LEFT(A$1,4),IF(MONTH(DATEVALUE(A10&" 1"))+1>12,1,MONTH(DATEVALUE(A10&" 1"))+1),1),"mmm")&" " &DAY(EOMONTH((DATE(LEFT(A$1,4),MONTH(DATEVALUE(A10&" 1"))+1,1)),0)+1-WEEKDAY(EOMONTH((DATE(LEFT(A$1,4),MONTH(DATEVALUE(A10&" 1"))+1,1)),0)+1-4)) -> Oct 29
A11: OCT | C11: =IF(B11<>"",((LEN(B11)-LEN(SUBSTITUTE(B11,",","")))/LEN(",")+1)+((LEN(B11)-LEN(SUBSTITUTE(B11,"/","")))/LEN("/")/2)- ((LEN(B11)-LEN(SUBSTITUTE(B11,"/","")))/LEN("/")),0) -> 0 | D11: =ROUND((((C11*7.5)/9)+(C11*7.5)), 2) -> 0 | E11: =D11*B15 -> 0 | F11: =IF(B$16<>0,B$16*D11-E11,0) -> 0 | G11: =IF(B16<>0,E11+SUM(F8:F10),0) -> 0 | H11: =IF(G11="",IF((((E11-I11)/4)-155)>0,((((E11-I11)/4)-155)*0.12)*4,0),IF((((G11-I11)/4)-155)>0,((((G11-I11)/4)-155)*0.12)*4,0)) -> 0 | I11: =IF(B$17<>"N",IF(G11="",E11*0.05,G11*0.05),0) -> 0 | J11: =IF(SUM(E$2:E11)>11000,E11-11000*0.2,0) -> 0 | K11: =IF(G11="",E11-H11-I11-J11,G11-H11-I11-J11) -> 0 | L11: =TEXT(DATE(LEFT(A$1,4),IF(MONTH(DATEVALUE(A11&" 1"))+1>12,1,MONTH(DATEVALUE(A11&" 1"))+1),1),"mmm")&" " &DAY(EOMONTH((DATE(LEFT(A$1,4),MONTH(DATEVALUE(A11&" 1"))+1,1)),0)+1-WEEKDAY(EOMONTH((DATE(LEFT(A$1,4),MONTH(DATEVALUE(A11&" 1"))+1,1)),0)+1-4)) -> Nov 26
A12: NOV | C12: =IF(B12<>"",((LEN(B12)-LEN(SUBSTITUTE(B12,",","")))/LEN(",")+1)+((LEN(B12)-LEN(SUBSTITUTE(B12,"/","")))/LEN("/")/2)- ((LEN(B12)-LEN(SUBSTITUTE(B12,"/","")))/LEN("/")),0) -> 0 | D12: =ROUND((((C12*7.5)/9)+(C12*7.5)), 2) -> 0 | E12: =D12*B15 -> 0 | F12: =IF(B$16<>0,B$16*D12-E12,0) -> 0 | H12: =IF(G12="",IF((((E12-I12)/4)-155)>0,((((E12-I12)/4)-155)*0.12)*4,0),IF((((G12-I12)/4)-155)>0,((((G12-I12)/4)-155)*0.12)*4,0)) -> 0 | I12: =IF(B$17<>"N",IF(G12="",E12*0.05,G12*0.05),0) -> 0 | J12: =IF(SUM(E$2:E12)>11000,E12-11000*0.2,0) -> 0 | K12: =IF(G12="",E12-H12-I12-J12,G12-H12-I12-J12) -> 0 | L12: ="Dec 24" -> Dec 24
A13: DEC | C13: =IF(B13<>"",((LEN(B13)-LEN(SUBSTITUTE(B13,",","")))/LEN(",")+1)+((LEN(B13)-LEN(SUBSTITUTE(B13,"/","")))/LEN("/")/2)- ((LEN(B13)-LEN(SUBSTITUTE(B13,"/","")))/LEN("/")),0) -> 0 | D13: =ROUND((((C13*7.5)/9)+(C13*7.5)), 2) -> 0 | E13: =D13*B15 -> 0 | F13: =IF(B$16<>0,B$16*D13-E13,0) -> 0 | H13: =IF(G13="",IF((((E13-I13)/4)-155)>0,((((E13-I13)/4)-155)*0.12)*4,0),IF((((G13-I13)/4)-155)>0,((((G13-I13)/4)-155)*0.12)*4,0)) -> 0 | I13: =IF(B$17<>"N",IF(G13="",E13*0.05,G13*0.05),0) -> 0 | J13: =IF(SUM(E$2:E13)>11000,E13-11000*0.2,0) -> 0 | K13: =IF(G13="",E13-H13-I13-J13,G13-H13-I13-J13) -> 0 | L13: =TEXT(DATE(LEFT(A$1,4),IF(MONTH(DATEVALUE(A13&" 1"))+1>12,1,MONTH(DATEVALUE(A13&" 1"))+1),1),"mmm")&" " &DAY(EOMONTH((DATE(LEFT(A$1,4),MONTH(DATEVALUE(A13&" 1"))+1,1)),0)+1-WEEKDAY(EOMONTH((DATE(LEFT(A$1,4),MONTH(DATEVALUE(A13&" 1"))+1,1)),0)+1-4)) -> Jan 28
I14: ="SUM: " & ROUND(SUM(I8:I13),2) -> SUM: 0 | K14: ="SUM: "& ROUND(SUM(K2:K13),2) -> SUM: 2200.72 | M14: ="SUM: " & SUM(M2:M13) -> SUM: 2485.5 | N14: ="SUM: "& ROUND(SUM(N2:N13),2) -> SUM: -241.82 | O14: ="SUM: "& ROUND(SUM(O2:O13),2) -> SUM: 676.98
A15: Hourly Rate: | B15: 7.3102
A16: Bonus Rate | B16: 0
A17: Pension | B17: N
A19: Missing Hours
A21: 41820 | B21: 07.30-15.30 | C21: 7.5
A22: 41821 | B22: 07.30-15.30 | C22: 7.5
A23: 41822 | B23: 07.30-15.30 | C23: 7.5
A24: 41823 | B24: 07.30-15.30 | C24: 7.5
A25: 41824 | B25: 07.30-15.30 | C25: 7.5
A26: 41827 | B26: 07.30-15.30 | C26: 7.5
A27: 41828 | B27: 07.30-15.30 | C27: 7.5
A28: 41829 | B28: 07.30-15.30 | C28: 7.5
A29: 41830 | B29: 07.30-15.30 | C29: 7.5
A30: 41831 | B30: 07.30-15.30 | C30: 7.5
A31: Additional Holiday hours | C31: =SUM(C21:C30)/9 -> 8.3333333
A32: Additional Total | D32: =SUM(C21:C31) -> 83.333333 | E32: =SUM(D32*7.3102) -> 609.18333
A34: Revised Total | D34: =SUM(D32+D15) -> 83.333333 | E34: =SUM(E32+E15) -> 609.18333

Sheet Wages 2015
A1: 2015/Month | B1: Dates worked | C1: Days | D1: Hours | E1: Total Earned | F1: Total Bonus | G1: Pay + Bonus | H1: NI (12%) | I1: Pension (5%) | J1: Income Tax (%20) | K1: Expected | L1: Payday | M1: Total Paid (on date) | N1: Total Missing | O1: Missing Paid On
A2: JAN | C2: =IF(B2<>"",((LEN(B2)-LEN(SUBSTITUTE(B2,",","")))/LEN(",")+1)+((LEN(B2)-LEN(SUBSTITUTE(B2,"/","")))/LEN("/")/2)- ((LEN(B2)-LEN(SUBSTITUTE(B2,"/","")))/LEN("/")),0) -> 0 | D2: =ROUND((((C2*7.5)/9)+(C2*7.5)), 2) -> 0 | E2: =D2*B15 -> 0 | F2: =B$16*D2-E2 -> 0 | G2: =IF(B16<>0,IF(ISREF(INDIRECT("'"&"Wages "&LEFT(A1,4)-1&"'!A1"))=TRUE,INDIRECT(CONCATENATE("'Wages ",LEFT(A1,4)-1,"'!F11")) + INDIRECT(CONCATENATE("'Wages ",LEFT(A1,4)-1,"'!F12")) + INDIRECT(CONCATENATE("'Wages ",LEFT(A1,4)-1,"'!F13")),""),0) -> 0 | H2: =IF(G2="",IF((((E2-I2)/4)-155)>0,((((E2-I2)/4)-155)*0.12)*4,0),IF((((G2-I2)/4)-155)>0,((((G2-I2)/4)-155)*0.12)*4,0)) -> 0 | I2: =IF(G2="",E2*0.05,G2*0.05) -> 0 | J2: =IF(E2>11000,E2-11000*0.2,0) -> 0 | K2: =IF(G2="",E2-H2-I2-J2,G2-H2-I2-J2) -> 0 | L2: =TEXT(DATE(LEFT(A$1,4),IF(MONTH(DATEVALUE(A2&" 1"))+1>12,1,MONTH(DATEVALUE(A2&" 1"))+1),1),"mmm")&" " &DAY(EOMONTH((DATE(LEFT(A$1,4),MONTH(DATEVALUE(A2&" 1"))+1,1)),0)+1-WEEKDAY(EOMONTH((DATE(LEFT(A$1,4),MONTH(DATEVALUE(A2&" 1"))+1,1)),0)+1-4)) -> Feb 25
A3: FEB | C3: =IF(B3<>"",((LEN(B3)-LEN(SUBSTITUTE(B3,",","")))/LEN(",")+1)+((LEN(B3)-LEN(SUBSTITUTE(B3,"/","")))/LEN("/")/2)- ((LEN(B3)-LEN(SUBSTITUTE(B3,"/","")))/LEN("/")),0) -> 0 | D3: =ROUND((((C3*7.5)/9)+(C3*7.5)), 2) -> 0 | E3: =D3*B15 -> 0 | F3: =B$16*D3-E3 -> 0 | H3: =IF(G3="",IF((((E3-I3)/4)-155)>0,((((E3-I3)/4)-155)*0.12)*4,0),IF((((G3-I3)/4)-155)>0,((((G3-I3)/4)-155)*0.12)*4,0)) -> 0 | I3: =IF(G3="",E3*0.05,G3*0.05) -> 0 | J3: =IF(SUM(E$2:E3)>11000,E3-11000*0.2,0) -> 0 | K3: =IF(G3="",E3-H3-I3-J3,G3-H3-I3-J3) -> 0 | L3: =TEXT(DATE(LEFT(A$1,4),IF(MONTH(DATEVALUE(A3&" 1"))+1>12,1,MONTH(DATEVALUE(A3&" 1"))+1),1),"mmm")&" " &DAY(EOMONTH((DATE(LEFT(A$1,4),MONTH(DATEVALUE(A3&" 1"))+1,1)),0)+1-WEEKDAY(EOMONTH((DATE(LEFT(A$1,4),MONTH(DATEVALUE(A3&" 1"))+1,1)),0)+1-4)) -> Mar 25
A4: MAR | C4: =IF(B4<>"",((LEN(B4)-LEN(SUBSTITUTE(B4,",","")))/LEN(",")+1)+((LEN(B4)-LEN(SUBSTITUTE(B4,"/","")))/LEN("/")/2)- ((LEN(B4)-LEN(SUBSTITUTE(B4,"/","")))/LEN("/")),0) -> 0 | D4: =ROUND((((C4*7.5)/9)+(C4*7.5)), 2) -> 0 | E4: =D4*B15 -> 0 | F4: =B$16*D4-E4 -> 0 | H4: =IF(G4="",IF((((E4-I4)/4)-155)>0,((((E4-I4)/4)-155)*0.12)*4,0),IF((((G4-I4)/4)-155)>0,((((G4-I4)/4)-155)*0.12)*4,0)) -> 0 | I4: =IF(G4="",E4*0.05,G4*0.05) -> 0 | J4: =IF(SUM(E$2:E4)>11000,E4-11000*0.2,0) -> 0 | K4: =IF(G4="",E4-H4-I4-J4,G4-H4-I4-J4) -> 0 | L4: =TEXT(DATE(LEFT(A$1,4),IF(MONTH(DATEVALUE(A4&" 1"))+1>12,1,MONTH(DATEVALUE(A4&" 1"))+1),1),"mmm")&" " &DAY(EOMONTH((DATE(LEFT(A$1,4),MONTH(DATEVALUE(A4&" 1"))+1,1)),0)+1-WEEKDAY(EOMONTH((DATE(LEFT(A$1,4),MONTH(DATEVALUE(A4&" 1"))+1,1)),0)+1-4)) -> Apr 29
A5: APR | C5: =IF(B5<>"",((LEN(B5)-LEN(SUBSTITUTE(B5,",","")))/LEN(",")+1)+((LEN(B5)-LEN(SUBSTITUTE(B5,"/","")))/LEN("/")/2)- ((LEN(B5)-LEN(SUBSTITUTE(B5,"/","")))/LEN("/")),0) -> 0 | D5: =ROUND((((C5*7.5)/9)+(C5*7.5)), 2) -> 0 | E5: =D5*B15 -> 0 | F5: =B$16*D5-E5 -> 0 | G5: =IF(B16<>0,E5+SUM(F2:F4),0) -> 0 | H5: =IF(G5="",IF((((E5-I5)/4)-155)>0,((((E5-I5)/4)-155)*0.12)*4,0),IF((((G5-I5)/4)-155)>0,((((G5-I5)/4)-155)*0.12)*4,0)) -> 0 | I5: =IF(G5="",E5*0.05,G5*0.05) -> 0 | J5: =IF(SUM(E$2:E5)>11000,E5-11000*0.2,0) -> 0 | K5: =IF(G5="",E5-H5-I5-J5,G5-H5-I5-J5) -> 0 | L5: =TEXT(DATE(LEFT(A$1,4),IF(MONTH(DATEVALUE(A5&" 1"))+1>12,1,MONTH(DATEVALUE(A5&" 1"))+1),1),"mmm")&" " &DAY(EOMONTH((DATE(LEFT(A$1,4),MONTH(DATEVALUE(A5&" 1"))+1,1)),0)+1-WEEKDAY(EOMONTH((DATE(LEFT(A$1,4),MONTH(DATEVALUE(A5&" 1"))+1,1)),0)+1-4)) -> May 27 | M5: 317.47
A6: MAY | C6: =IF(B6<>"",((LEN(B6)-LEN(SUBSTITUTE(B6,",","")))/LEN(",")+1)+((LEN(B6)-LEN(SUBSTITUTE(B6,"/","")))/LEN("/")/2)- ((LEN(B6)-LEN(SUBSTITUTE(B6,"/","")))/LEN("/")),0) -> 0 | D6: =ROUND((((C6*7.5)/9)+(C6*7.5)), 2) -> 0 | E6: =D6*B15 -> 0 | F6: =B$16*D6-E6 -> 0 | H6: =IF(G6="",IF((((E6-I6)/4)-155)>0,((((E6-I6)/4)-155)*0.12)*4,0),IF((((G6-I6)/4)-155)>0,((((G6-I6)/4)-155)*0.12)*4,0)) -> 0 | I6: =IF(G6="",E6*0.05,G6*0.05) -> 0 | J6: =IF(SUM(E$2:E6)>11000,E6-11000*0.2,0) -> 0 | K6: =IF(G6="",E6-H6-I6-J6,G6-H6-I6-J6) -> 0 | L6: =TEXT(DATE(LEFT(A$1,4),IF(MONTH(DATEVALUE(A6&" 1"))+1>12,1,MONTH(DATEVALUE(A6&" 1"))+1),1),"mmm")&" " &DAY(EOMONTH((DATE(LEFT(A$1,4),MONTH(DATEVALUE(A6&" 1"))+1,1)),0)+1-WEEKDAY(EOMONTH((DATE(LEFT(A$1,4),MONTH(DATEVALUE(A6&" 1"))+1,1)),0)+1-4)) -> Jun 24 | M6: 816.81
A7: JUN | C7: =IF(B7<>"",((LEN(B7)-LEN(SUBSTITUTE(B7,",","")))/LEN(",")+1)+((LEN(B7)-LEN(SUBSTITUTE(B7,"/","")))/LEN("/")/2)- ((LEN(B7)-LEN(SUBSTITUTE(B7,"/","")))/LEN("/")),0) -> 0 | D7: =ROUND((((C7*7.5)/9)+(C7*7.5)), 2) -> 0 | E7: =D7*B15 -> 0 | F7: =B$16*D7-E7 -> 0 | H7: =IF(G7="",IF((((E7-I7)/4)-155)>0,((((E7-I7)/4)-155)*0.12)*4,0),IF((((G7-I7)/4)-155)>0,((((G7-I7)/4)-155)*0.12)*4,0)) -> 0 | I7: =IF(G7="",E7*0.05,G7*0.05) -> 0 | J7: =IF(SUM(E$2:E7)>11000,E7-11000*0.2,0) -> 0 | K7: =IF(G7="",E7-H7-I7-J7,G7-H7-I7-J7) -> 0 | L7: =TEXT(DATE(LEFT(A$1,4),IF(MONTH(DATEVALUE(A7&" 1"))+1>12,1,MONTH(DATEVALUE(A7&" 1"))+1),1),"mmm")&" " &DAY(EOMONTH((DATE(LEFT(A$1,4),MONTH(DATEVALUE(A7&" 1"))+1,1)),0)+1-WEEKDAY(EOMONTH((DATE(LEFT(A$1,4),MONTH(DATEVALUE(A7&" 1"))+1,1)),0)+1-4)) -> Jul 29 | M7: 760.21
A8: JUL | C8: =IF(B8<>"",((LEN(B8)-LEN(SUBSTITUTE(B8,",","")))/LEN(",")+1)+((LEN(B8)-LEN(SUBSTITUTE(B8,"/","")))/LEN("/")/2)- ((LEN(B8)-LEN(SUBSTITUTE(B8,"/","")))/LEN("/")),0) -> 0 | D8: =ROUND((((C8*7.5)/9)+(C8*7.5)), 2) -> 0 | E8: =D8*B15 -> 0 | F8: =B$16*D8-E8 -> 0 | G8: =IF(B16<>0,E8+SUM(F5:F7),0) -> 0 | H8: =IF(G8="",IF((((E8-I8)/4)-155)>0,((((E8-I8)/4)-155)*0.12)*4,0),IF((((G8-I8)/4)-155)>0,((((G8-I8)/4)-155)*0.12)*4,0)) -> 0 | I8: =IF(G8="",E8*0.05,G8*0.05) -> 0 | J8: =IF(SUM(E$2:E8)>11000,E8-11000*0.2,0) -> 0 | K8: =IF(G8="",E8-H8-I8-J8,G8-H8-I8-J8) -> 0 | L8: =TEXT(DATE(LEFT(A$1,4),IF(MONTH(DATEVALUE(A8&" 1"))+1>12,1,MONTH(DATEVALUE(A8&" 1"))+1),1),"mmm")&" " &DAY(EOMONTH((DATE(LEFT(A$1,4),MONTH(DATEVALUE(A8&" 1"))+1,1)),0)+1-WEEKDAY(EOMONTH((DATE(LEFT(A$1,4),MONTH(DATEVALUE(A8&" 1"))+1,1)),0)+1-4)) -> Aug 26 | M8: 788.55
A9: AUG | C9: =IF(B9<>"",((LEN(B9)-LEN(SUBSTITUTE(B9,",","")))/LEN(",")+1)+((LEN(B9)-LEN(SUBSTITUTE(B9,"/","")))/LEN("/")/2)- ((LEN(B9)-LEN(SUBSTITUTE(B9,"/","")))/LEN("/")),0) -> 0 | D9: =ROUND((((C9*7.5)/9)+(C9*7.5)), 2) -> 0 | E9: =D9*B15 -> 0 | F9: =B$16*D9-E9 -> 0 | H9: =IF(G9="",IF((((E9-I9)/4)-155)>0,((((E9-I9)/4)-155)*0.12)*4,0),IF((((G9-I9)/4)-155)>0,((((G9-I9)/4)-155)*0.12)*4,0)) -> 0 | I9: =IF(G9="",E9*0.05,G9*0.05) -> 0 | J9: =IF(SUM(E$2:E9)>11000,E9-11000*0.2,0) -> 0 | K9: =IF(G9="",E9-H9-I9-J9,G9-H9-I9-J9) -> 0 | L9: =TEXT(DATE(LEFT(A$1,4),IF(MONTH(DATEVALUE(A9&" 1"))+1>12,1,MONTH(DATEVALUE(A9&" 1"))+1),1),"mmm")&" " &DAY(EOMONTH((DATE(LEFT(A$1,4),MONTH(DATEVALUE(A9&" 1"))+1,1)),0)+1-WEEKDAY(EOMONTH((DATE(LEFT(A$1,4),MONTH(DATEVALUE(A9&" 1"))+1,1)),0)+1-4)) -> Sep 30 | M9: 257.39 | O9: Late
A10: SEP | C10: =IF(B10<>"",((LEN(B10)-LEN(SUBSTITUTE(B10,",","")))/LEN(",")+1)+((LEN(B10)-LEN(SUBSTITUTE(B10,"/","")))/LEN("/")/2)- ((LEN(B10)-LEN(SUBSTITUTE(B10,"/","")))/LEN("/")),0) -> 0 | D10: =ROUND((((C10*7.5)/9)+(C10*7.5)), 2) -> 0 | E10: =D10*B15 -> 0 | F10: =B$16*D10-E10 -> 0 | H10: =IF(G10="",IF((((E10-I10)/4)-155)>0,((((E10-I10)/4)-155)*0.12)*4,0),IF((((G10-I10)/4)-155)>0,((((G10-I10)/4)-155)*0.12)*4,0)) -> 0 | I10: =IF(G10="",E10*0.05,G10*0.05) -> 0 | J10: =IF(SUM(E$2:E10)>11000,E10-11000*0.2,0) -> 0 | K10: =IF(G10="",E10-H10-I10-J10,G10-H10-I10-J10) -> 0 | L10: =TEXT(DATE(LEFT(A$1,4),IF(MONTH(DATEVALUE(A10&" 1"))+1>12,1,MONTH(DATEVALUE(A10&" 1"))+1),1),"mmm")&" " &DAY(EOMONTH((DATE(LEFT(A$1,4),MONTH(DATEVALUE(A10&" 1"))+1,1)),0)+1-WEEKDAY(EOMONTH((DATE(LEFT(A$1,4),MONTH(DATEVALUE(A10&" 1"))+1,1)),0)+1-4)) -> Oct 28
A11: OCT | C11: =IF(B11<>"",((LEN(B11)-LEN(SUBSTITUTE(B11,",","")))/LEN(",")+1)+((LEN(B11)-LEN(SUBSTITUTE(B11,"/","")))/LEN("/")/2)- ((LEN(B11)-LEN(SUBSTITUTE(B11,"/","")))/LEN("/")),0) -> 0 | D11: =ROUND((((C11*7.5)/9)+(C11*7.5)), 2) -> 0 | E11: =D11*B15 -> 0 | F11: =B$16*D11-E11 -> 0 | G11: =IF(B16<>0,E11+SUM(F8:F10),0) -> 0 | H11: =IF(G11="",IF((((E11-I11)/4)-155)>0,((((E11-I11)/4)-155)*0.12)*4,0),IF((((G11-I11)/4)-155)>0,((((G11-I11)/4)-155)*0.12)*4,0)) -> 0 | I11: =IF(G11="",E11*0.05,G11*0.05) -> 0 | J11: =IF(SUM(E$2:E11)>11000,E11-11000*0.2,0) -> 0 | K11: =IF(G11="",E11-H11-I11-J11,G11-H11-I11-J11) -> 0 | L11: =TEXT(DATE(LEFT(A$1,4),IF(MONTH(DATEVALUE(A11&" 1"))+1>12,1,MONTH(DATEVALUE(A11&" 1"))+1),1),"mmm")&" " &DAY(EOMONTH((DATE(LEFT(A$1,4),MONTH(DATEVALUE(A11&" 1"))+1,1)),0)+1-WEEKDAY(EOMONTH((DATE(LEFT(A$1,4),MONTH(DATEVALUE(A11&" 1"))+1,1)),0)+1-4)) -> Nov 25 | M11: 321.79 | O11: Late
A12: NOV | C12: =IF(B12<>"",((LEN(B12)-LEN(SUBSTITUTE(B12,",","")))/LEN(",")+1)+((LEN(B12)-LEN(SUBSTITUTE(B12,"/","")))/LEN("/")/2)- ((LEN(B12)-LEN(SUBSTITUTE(B12,"/","")))/LEN("/")),0) -> 0 | D12: =ROUND((((C12*7.5)/9)+(C12*7.5)), 2) -> 0 | E12: =D12*B15 -> 0 | F12: =B$16*D12-E12 -> 0 | H12: =IF(G12="",IF((((E12-I12)/4)-155)>0,((((E12-I12)/4)-155)*0.12)*4,0),IF((((G12-I12)/4)-155)>0,((((G12-I12)/4)-155)*0.12)*4,0)) -> 0 | J12: =IF(SUM(E$2:E12)>11000,E12-11000*0.2,0) -> 0 | K12: =IF(G12="",E12-H12-I12-J12,G12-H12-I12-J12) -> 0 | L12: ="Dec 23" -> Dec 23 | M12: 333.27 | O12: Late
A13: DEC | C13: =IF(B13<>"",((LEN(B13)-LEN(SUBSTITUTE(B13,",","")))/LEN(",")+1)+((LEN(B13)-LEN(SUBSTITUTE(B13,"/","")))/LEN("/")/2)- ((LEN(B13)-LEN(SUBSTITUTE(B13,"/","")))/LEN("/")),0) -> 0 | D13: =ROUND((((C13*7.5)/9)+(C13*7.5)), 2) -> 0 | E13: =D13*B15 -> 0 | F13: =B$16*D13-E13 -> 0 | H13: =IF(G13="",IF((((E13-I13)/4)-155)>0,((((E13-I13)/4)-155)*0.12)*4,0),IF((((G13-I13)/4)-155)>0,((((G13-I13)/4)-155)*0.12)*4,0)) -> 0 | J13: =IF(SUM(E$2:E13)>11000,E13-11000*0.2,0) -> 0 | K13: =IF(G13="",E13-H13-I13-J13,G13-H13-I13-J13) -> 0 | L13: =TEXT(DATE(LEFT(A$1,4),IF(MONTH(DATEVALUE(A13&" 1"))+1>12,1,MONTH(DATEVALUE(A13&" 1"))+1),1),"mmm")&" " &DAY(EOMONTH((DATE(LEFT(A$1,4),MONTH(DATEVALUE(A13&" 1"))+1,1)),0)+1-WEEKDAY(EOMONTH((DATE(LEFT(A$1,4),MONTH(DATEVALUE(A13&" 1"))+1,1)),0)+1-4)) -> Jan 27 | M13: 411.84
I14: ="SUM: " & ROUND(SUM(I8:I13),2) -> SUM: 0 | K14: ="SUM: "& ROUND(SUM(K2:K13),2) -> SUM: 0 | M14: ="SUM: " & SUM(M2:M13) -> SUM: 4007.33
A15: Hourly Rate: | B15: 7.7224
A16: Bonus Rate | B16: 0
A17: Pension | B17: N

Sheet Wages 2016
A1: 2016/Month | B1: Days worked | C1: Hours | D1: Total Days | E1: Total Hours | F1: Total Earned | G1: Total Bonus | H1: Pay + Bonus | I1: NI (12%) | J1: Pension (5%) | K1: Income Tax (%20) | L1: Expected | M1: Payday | N1: Total Paid (on date) | O1: Total Missing | P1: Missing Paid On | Q1: Sum to date (Tax year)
A2: JAN | B2: 19, 20, 26, 27 | D2: =IF(B2<>"",((LEN(B2)-LEN(SUBSTITUTE(B2,",","")))/LEN(",")+1)+((LEN(B2)-LEN(SUBSTITUTE(B2,"/","")))/LEN("/")/2)- ((LEN(B2)-LEN(SUBSTITUTE(B2,"/","")))/LEN("/")),0) -> 4 | E2: =ROUND((((D2*7.5)/9)+(D2*7.5)), 2) -> 33.33 | F2: =E2*B19 -> 259.96067 | G2: =8.25*E2-F2 -> 15.011832 | H2: =IF(B20<>0,IF(ISREF(INDIRECT("'"&"Wages "&LEFT(A1,4)-1&"'!A1"))=TRUE,INDIRECT(CONCATENATE("'Wages ",LEFT(A1,4)-1,"'!F11")) + INDIRECT(CONCATENATE("'Wages ",LEFT(A1,4)-1,"'!F12")) + INDIRECT(CONCATENATE("'Wages ",LEFT(A1,4)-1,"'!F13")),""),0) -> 0 | I2: =IF(H2="",IF((((F2-J2)/4)-155)>0,((((F2-J2)/4)-155)*0.12)*4,0),IF((((H2-J2)/4)-155)>0,((((H2-J2)/4)-155)*0.12)*4,0)) -> 0 | J2: =IF(H2="",F2*0.05,H2*0.05) -> 0 | K2: =IF(F2>11000,F2-11000*0.2,0) -> 0 | L2: =IF(H2="",F2-I2-J2-K2,H2-I2-J2-K2) -> 0 | M2: =TEXT(DATE(LEFT(A$1,4),IF(MONTH(DATEVALUE(A2&" 1"))+1>12,1,MONTH(DATEVALUE(A2&" 1"))+1),1),"mmm")&" " &DAY(EOMONTH((DATE(LEFT(A$1,4),MONTH(DATEVALUE(A2&" 1"))+1,1)),0)+1-WEEKDAY(EOMONTH((DATE(LEFT(A$1,4),MONTH(DATEVALUE(A2&" 1"))+1,1)),0)+1-4)) -> Feb 24 | N2: 321.79 | Q2: =F2 -> 259.96067
A3: FEB | B3: 2, 3, 9, 10, 17, 18, 19, 23, 24 | D3: =IF(B3<>"",((LEN(B3)-LEN(SUBSTITUTE(B3,",","")))/LEN(",")+1)+((LEN(B3)-LEN(SUBSTITUTE(B3,"/","")))/LEN("/")/2)- ((LEN(B3)-LEN(SUBSTITUTE(B3,"/","")))/LEN("/")),0) -> 9 | E3: =ROUND((((D3*7.5)/9)+(D3*7.5)), 2) -> 75 | F3: =E3*B19 -> 584.97 | G3: =8.25*E3-F3 -> 33.78 | I3: =IF(H3="",IF((((F3-J3)/4)-155)>0,((((F3-J3)/4)-155)*0.12)*4,0),IF((((H3-J3)/4)-155)>0,((((H3-J3)/4)-155)*0.12)*4,0)) -> 0 | J3: =IF(H3="",F3*0.05,H3*0.05) -> 29.2485 | K3: =IF(SUM(F$2:F3)>11000,F3-11000*0.2,0) -> 0 | L3: =IF(H3="",F3-I3-J3-K3,H3-I3-J3-K3) -> 555.7215 | M3: =TEXT(DATE(LEFT(A$1,4),IF(MONTH(DATEVALUE(A3&" 1"))+1>12,1,MONTH(DATEVALUE(A3&" 1"))+1),1),"mmm")&" " &DAY(EOMONTH((DATE(LEFT(A$1,4),MONTH(DATEVALUE(A3&" 1"))+1,1)),0)+1-WEEKDAY(EOMONTH((DATE(LEFT(A$1,4),MONTH(DATEVALUE(A3&" 1"))+1,1)),0)+1-4)) -> Mar 30 | N3: 643.51 | O3: =L3-N3 -> -87.7885 | Q3: =Q2+F3 -> 844.93067
A4: MAR | B4: 1, 2, 8, 9(1/2), 15, 16, 22, 23, 24 | D4: =IF(B4<>"",((LEN(B4)-LEN(SUBSTITUTE(B4,",","")))/LEN(",")+1)+((LEN(B4)-LEN(SUBSTITUTE(B4,"/","")))/LEN("/")/2)- ((LEN(B4)-LEN(SUBSTITUTE(B4,"/","")))/LEN("/")),0) -> 8.5 | E4: =ROUND((((D4*7.5)/9)+(D4*7.5)), 2) -> 70.83 | F4: =E4*B19 -> 552.44567 | G4: =8.25*E4-F4 -> 31.901832 | I4: =IF(H4="",IF((((F4-J4)/4)-155)>0,((((F4-J4)/4)-155)*0.12)*4,0),IF((((H4-J4)/4)-155)>0,((((H4-J4)/4)-155)*0.12)*4,0)) -> 0 | J4: =IF(H4="",F4*0.05,H4*0.05) -> 27.622283 | K4: =IF(SUM(F$2:F4)>11000,F4-11000*0.2,0) -> 0 | L4: =IF(H4="",F4-I4-J4-K4,H4-I4-J4-K4) -> 524.82338 | M4: =TEXT(DATE(LEFT(A$1,4),IF(MONTH(DATEVALUE(A4&" 1"))+1>12,1,MONTH(DATEVALUE(A4&" 1"))+1),1),"mmm")&" " &DAY(EOMONTH((DATE(LEFT(A$1,4),MONTH(DATEVALUE(A4&" 1"))+1,1)),0)+1-WEEKDAY(EOMONTH((DATE(LEFT(A$1,4),MONTH(DATEVALUE(A4&" 1"))+1,1)),0)+1-4)) -> Apr 27 | N4: 579.76 | O4: =L4-N4 -> -54.936615 | Q4: =Q3+F4 -> 1397.3763
A5: APR | B5: 12, 13, 19, 20 | D5: =IF(B5<>"",((LEN(B5)-LEN(SUBSTITUTE(B5,",","")))/LEN(",")+1)+((LEN(B5)-LEN(SUBSTITUTE(B5,"/","")))/LEN("/")/2)- ((LEN(B5)-LEN(SUBSTITUTE(B5,"/","")))/LEN("/")),0) -> 4 | E5: =ROUND((((D5*7.5)/9)+(D5*7.5)), 2) -> 33.33 | F5: =E5*B19 -> 259.96067 | G5: =8.25*E5-F5 -> 15.011832 | H5: =IF(B20<>0,F5+SUM(G2:G4),0) -> 340.65433 | I5: =IF(H5="",IF((((F5-J5)/4)-155)>0,((((F5-J5)/4)-155)*0.12)*4,0),IF((((H5-J5)/4)-155)>0,((((H5-J5)/4)-155)*0.12)*4,0)) -> 0 | J5: =IF(H5="",F5*0.05,H5*0.05) -> 17.032717 | K5: =IF(SUM(F$2:F5)>11000,F5-11000*0.2,0) -> 0 | L5: =IF(H5="",F5-I5-J5-K5,H5-I5-J5-K5) -> 323.62162 | M5: =TEXT(DATE(LEFT(A$1,4),IF(MONTH(DATEVALUE(A5&" 1"))+1>12,1,MONTH(DATEVALUE(A5&" 1"))+1),1),"mmm")&" " &DAY(EOMONTH((DATE(LEFT(A$1,4),MONTH(DATEVALUE(A5&" 1"))+1,1)),0)+1-WEEKDAY(EOMONTH((DATE(LEFT(A$1,4),MONTH(DATEVALUE(A5&" 1"))+1,1)),0)+1-4)) -> May 25 | N5: 259.96 | O5: =L5-N5 -> 63.661615 | Q5: =F5 -> 259.96067
A6: MAY | B6: 16, 17, 18, 19, 20, 23, 24, 25, 26, 27 | D6: =IF(B6<>"",((LEN(B6)-LEN(SUBSTITUTE(B6,",","")))/LEN(",")+1)+((LEN(B6)-LEN(SUBSTITUTE(B6,"/","")))/LEN("/")/2)- ((LEN(B6)-LEN(SUBSTITUTE(B6,"/","")))/LEN("/")),0) -> 10 | E6: =ROUND((((D6*7.5)/9)+(D6*7.5)), 2) -> 83.33 | F6: =E6*B19 -> 649.94067 | G6: =8.25*E6-F6 -> 37.531832 | I6: =IF(H6="",IF((((F6-J6)/4)-155)>0,((((F6-J6)/4)-155)*0.12)*4,0),IF((((H6-J6)/4)-155)>0,((((H6-J6)/4)-155)*0.12)*4,0)) -> 0 | J6: =IF(H6="",F6*0.05,H6*0.05) -> 32.497033 | K6: =IF(SUM(F$2:F6)>11000,F6-11000*0.2,0) -> 0 | L6: =IF(H6="",F6-I6-J6-K6,H6-I6-J6-K6) -> 617.44363 | M6: =TEXT(DATE(LEFT(A$1,4),IF(MONTH(DATEVALUE(A6&" 1"))+1>12,1,MONTH(DATEVALUE(A6&" 1"))+1),1),"mmm")&" " &DAY(EOMONTH((DATE(LEFT(A$1,4),MONTH(DATEVALUE(A6&" 1"))+1,1)),0)+1-WEEKDAY(EOMONTH((DATE(LEFT(A$1,4),MONTH(DATEVALUE(A6&" 1"))+1,1)),0)+1-4)) -> Jun 29 | N6: 325.01 | O6: 305 | P6: 11110 | Q6: =Q5+N6 -> 584.97067
A7: JUN | B7: 30(1/2), 31(1/2), 1, 2, 3, 8, 9, 10, 15, 16, 17, 20, 21, 22, 23, 24 | D7: =IF(B7<>"",((LEN(B7)-LEN(SUBSTITUTE(B7,",","")))/LEN(",")+1)+((LEN(B7)-LEN(SUBSTITUTE(B7,"/","")))/LEN("/")/2)- ((LEN(B7)-LEN(SUBSTITUTE(B7,"/","")))/LEN("/")),0) -> 15 | E7: =ROUND((((D7*7.5)/9)+(D7*7.5)), 2) -> 125 | F7: =E7*B19 -> 974.95 | G7: =8.25*E7-F7 -> 56.3 | I7: =IF(H7="",IF((((F7-J7)/4)-155)>0,((((F7-J7)/4)-155)*0.12)*4,0),IF((((H7-J7)/4)-155)>0,((((H7-J7)/4)-155)*0.12)*4,0)) -> 36.7443 | J7: =IF(H7="",F7*0.05,H7*0.05) -> 48.7475 | K7: =IF(SUM(F$2:F7)>11000,F7-11000*0.2,0) -> 0 | L7: =IF(H7="",F7-I7-J7-K7,H7-I7-J7-K7) -> 889.4582 | M7: =TEXT(DATE(LEFT(A$1,4),IF(MONTH(DATEVALUE(A7&" 1"))+1>12,1,MONTH(DATEVALUE(A7&" 1"))+1),1),"mmm")&" " &DAY(EOMONTH((DATE(LEFT(A$1,4),MONTH(DATEVALUE(A7&" 1"))+1,1)),0)+1-WEEKDAY(EOMONTH((DATE(LEFT(A$1,4),MONTH(DATEVALUE(A7&" 1"))+1,1)),0)+1-4)) -> Jul 27 | N7: 993.29 | O7: =L7-N7 -> -103.8318 | Q7: =Q6+F7 -> 1559.9207
A8: JUL | B8: 11, 13, 14, 15, 18, 19(1/2), 20, 21, 22(1/2), 25, 26, 27, 28, 29 | D8: =IF(B8<>"",((LEN(B8)-LEN(SUBSTITUTE(B8,",","")))/LEN(",")+1)+((LEN(B8)-LEN(SUBSTITUTE(B8,"/","")))/LEN("/")/2)- ((LEN(B8)-LEN(SUBSTITUTE(B8,"/","")))/LEN("/")),0) -> 13 | E8: =ROUND((((D8*7.5)/9)+(D8*7.5)), 2) -> 108.33 | F8: =E8*B19 -> 844.93067 | G8: =8.25*E8-F8 -> 48.791832 | H8: =IF(B20<>0,F8+SUM(G5:G7),0) -> 953.77433 | I8: =IF(H8="",IF((((F8-J8)/4)-155)>0,((((F8-J8)/4)-155)*0.12)*4,0),IF((((H8-J8)/4)-155)>0,((((H8-J8)/4)-155)*0.12)*4,0)) -> 34.330274 | J8: =IF(H8="",F8*0.05,H8*0.05) -> 47.688717 | K8: =IF(SUM(F$2:F8)>11000,F8-11000*0.2,0) -> 0 | L8: =IF(H8="",F8-I8-J8-K8,H8-I8-J8-K8) -> 871.75534 | M8: =TEXT(DATE(LEFT(A$1,4),IF(MONTH(DATEVALUE(A8&" 1"))+1>12,1,MONTH(DATEVALUE(A8&" 1"))+1),1),"mmm")&" " &DAY(EOMONTH((DATE(LEFT(A$1,4),MONTH(DATEVALUE(A8&" 1"))+1,1)),0)+1-WEEKDAY(EOMONTH((DATE(LEFT(A$1,4),MONTH(DATEVALUE(A8&" 1"))+1,1)),0)+1-4)) -> Aug 31 | N8: 905.12 | O8: =L8-N8 -> -33.364658 | Q8: =Q7+F8 -> 2404.8513
A9: AUG | B9: 1, 2, 3, 4, 5, 8, 9, 10, 11, 12, 15, 16, 17, 18, 19 | D9: =IF(B9<>"",((LEN(B9)-LEN(SUBSTITUTE(B9,",","")))/LEN(",")+1)+((LEN(B9)-LEN(SUBSTITUTE(B9,"/","")))/LEN("/")/2)- ((LEN(B9)-LEN(SUBSTITUTE(B9,"/","")))/LEN("/")),0) -> 15 | E9: =ROUND((((D9*7.5)/9)+(D9*7.5)), 2) -> 125 | F9: =E9*B19 -> 974.95 | G9: =8.25*E9-F9 -> 56.3 | I9: =IF(H9="",IF((((F9-J9)/4)-155)>0,((((F9-J9)/4)-155)*0.12)*4,0),IF((((H9-J9)/4)-155)>0,((((H9-J9)/4)-155)*0.12)*4,0)) -> 36.7443 | J9: =IF(H9="",F9*0.05,H9*0.05) -> 48.7475 | K9: =IF(SUM(F$2:F9)>11000,F9-11000*0.2,0) -> 0 | L9: =IF(H9="",F9-I9-J9-K9,H9-I9-J9-K9) -> 889.4582 | M9: =TEXT(DATE(LEFT(A$1,4),IF(MONTH(DATEVALUE(A9&" 1"))+1>12,1,MONTH(DATEVALUE(A9&" 1"))+1),1),"mmm")&" " &DAY(EOMONTH((DATE(LEFT(A$1,4),MONTH(DATEVALUE(A9&" 1"))+1,1)),0)+1-WEEKDAY(EOMONTH((DATE(LEFT(A$1,4),MONTH(DATEVALUE(A9&" 1"))+1,1)),0)+1-4)) -> Sep 28 | N9: 910.51 | O9: =L9-N9 -> -21.0518 | Q9: =Q8+F9 -> 3379.8013
A10: SEP | B10: 5, 6, 7, 8, 9, 12(1/2), 13, 14, 15, 16, 20, 21, 23, 24, 26, 27, 28 | D10: =IF(B10<>"",((LEN(B10)-LEN(SUBSTITUTE(B10,",","")))/LEN(",")+1)+((LEN(B10)-LEN(SUBSTITUTE(B10,"/","")))/LEN("/")/2)- ((LEN(B10)-LEN(SUBSTITUTE(B10,"/","")))/LEN("/")),0) -> 16.5 | E10: =ROUND((((D10*7.5)/9)+(D10*7.5)), 2)+1 -> 138.5 | F10: =E10*B19 -> 1080.2446 | G10: =8.25*E10-F10 -> 62.3804 | I10: =IF(H10="",IF((((F10-J10)/4)-155)>0,((((F10-J10)/4)-155)*0.12)*4,0),IF((((H10-J10)/4)-155)>0,((((H10-J10)/4)-155)*0.12)*4,0)) -> 48.747884 | J10: =IF(H10="",F10*0.05,H10*0.05) -> 54.01223 | K10: =IF(SUM(F$2:F10)>11000,F10-11000*0.2,0) -> 0 | L10: =IF(H10="",F10-I10-J10-K10,H10-I10-J10-K10) -> 977.48449 | M10: =TEXT(DATE(LEFT(A$1,4),IF(MONTH(DATEVALUE(A10&" 1"))+1>12,1,MONTH(DATEVALUE(A10&" 1"))+1),1),"mmm")&" " &DAY(EOMONTH((DATE(LEFT(A$1,4),MONTH(DATEVALUE(A10&" 1"))+1,1)),0)+1-WEEKDAY(EOMONTH((DATE(LEFT(A$1,4),MONTH(DATEVALUE(A10&" 1"))+1,1)),0)+1-4)) -> Oct 26 | N10: 979.78 | O10: =L10-N10 -> -2.2955144 | Q10: =Q9+F10 -> 4460.0459
A11: OCT | B11: 3+, 4(^6), 5(£3), 6+, 10+, 11(^6), 12(£3), 13+, 17+, 18(^6), 19(£3), 20+, 24+, 25(^6), 26(£3), 27+ | D11: =IF(B11<>"",((LEN(B11)-LEN(SUBSTITUTE(B11,",","")))+1)) -> 16 | E11: =(ROUND((((D11*7.5)/9)+(D11*7.5)), 2) + (LEN(B11)-LEN(SUBSTITUTE(B11,"+","")))) - ((((LEN(B11)-LEN(SUBSTITUTE(B11,"^","")))*7.5)-((LEN(B11)-LEN(SUBSTITUTE(B11,"^","")))*6))+(((LEN(B11)-LEN(SUBSTITUTE(B11,"£","")))*7.5)-((LEN(B11)-LEN(SUBSTITUTE(B11,"£","")))*3)))+1 -> 118.33 | F11: =E11*B19 -> 922.92667 | G11: =8.25*E11-F11 -> 53.295832 | H11: =IF(B20<>0,F11+SUM(G8:G10),0) -> 1090.3989 | I11: =IF(H11="",IF((((F11-J11)/4)-155)>0,((((F11-J11)/4)-155)*0.12)*4,0),IF((((H11-J11)/4)-155)>0,((((H11-J11)/4)-155)*0.12)*4,0)) -> 49.905475 | J11: =IF(H11="",F11*0.05,H11*0.05) -> 54.519945 | K11: =IF(SUM(F$2:F11)>11000,F11-11000*0.2,0) -> 0 | L11: =IF(H11="",F11-I11-J11-K11,H11-I11-J11-K11) -> 985.97348 | M11: =TEXT(DATE(LEFT(A$1,4),IF(MONTH(DATEVALUE(A11&" 1"))+1>12,1,MONTH(DATEVALUE(A11&" 1"))+1),1),"mmm")&" " &DAY(EOMONTH((DATE(LEFT(A$1,4),MONTH(DATEVALUE(A11&" 1"))+1,1)),0)+1-WEEKDAY(EOMONTH((DATE(LEFT(A$1,4),MONTH(DATEVALUE(A11&" 1"))+1,1)),0)+1-4)) -> Nov 30 | N11: 950.62 | O11: =L11-N11 -> 35.35348 | Q11: =Q10+F11 -> 5382.9726
A12: NOV | B12: 31+, 1(^6), 3+, 7+, 8(^6), 9(£3), 10+, 14+, 17+, 18+, 21+, 22+, 23+, 24+, 25/ | D12: =IF(B12<>"",((LEN(B12)-LEN(SUBSTITUTE(B12,",","")))+1)) -> 15 | E12: =ROUND((((D12*7.5)/9)+(D12*7.5)), 2) - ((((LEN(B12)-LEN(SUBSTITUTE(B12,"^","")))*7.5)-((LEN(B12)-LEN(SUBSTITUTE(B12,"^","")))*6))+(((LEN(B12)-LEN(SUBSTITUTE(B12,"£","")))*7.5)-((LEN(B12)-LEN(SUBSTITUTE(B12,"£","")))*3))) + (LEN(B12)-LEN(SUBSTITUTE(B12,"+",""))) -> 128.5 | F12: =E12*B19 -> 1002.2486 | G12: =8.25*E12-F12 -> 57.8764 | I12: =IF(H12="",IF((((F12-J12)/4)-155)>0,((((F12-J12)/4)-155)*0.12)*4,0),IF((((H12-J12)/4)-155)>0,((((H12-J12)/4)-155)*0.12)*4,0)) -> 39.85634 | J12: =IF(H12="",F12*0.05,H12*0.05) -> 50.11243 | K12: =IF(SUM(F$2:F12)>11000,F12-11000*0.2,0) -> 0 | L12: =IF(H12="",F12-I12-J12-K12,H12-I12-J12-K12) -> 912.27983 | M12: ="Dec 21" -> Dec 21 | N12: 866.48 | O12: =L12-N12 -> 45.79983 | Q12: =Q11+F12 -> 6385.2212
A13: DEC | B13: =(IF(B14<>"",((LEN(B14)-LEN(SUBSTITUTE(B14,",","")))+1)))+(IF(B15<>"",((LEN(B15)-LEN(SUBSTITUTE(B15,",","")))+1)))+(IF(B16<>"",((LEN(B16)-LEN(SUBSTITUTE(B16,",","")))+1)))+(IF(B17<>"",((LEN(B17)-LEN(SUBSTITUTE(B17,",","")))+1))) -> 14 | C13: =ROUND(SUM(C14:C16)/9,2)+SUM(C14:C16) -> 102.22 | D13: =IF(B13<>"",((LEN(B13)-LEN(SUBSTITUTE(B13,",","")))+1)) -> 1 | F13: =C13*B19 -> 797.27511 | G13: =8.25*C13-F13 -> 46.039888 | I13: =IF(H13="",IF((((F13-J13)/4)-155)>0,((((F13-J13)/4)-155)*0.12)*4,0),IF((((H13-J13)/4)-155)>0,((((H13-J13)/4)-155)*0.12)*4,0)) -> 21.273013 | K13: =IF(SUM(F$2:F13)>11000,F13-11000*0.2,0) -> 0 | L13: =IF(H13="",F13-I13-J13-K13,H13-I13-J13-K13) -> 776.0021 | M13: =TEXT(DATE(LEFT(A$1,4),IF(MONTH(DATEVALUE(A13&" 1"))+1>12,1,MONTH(DATEVALUE(A13&" 1"))+1),1),"mmm")&" " &DAY(EOMONTH((DATE(LEFT(A$1,4),MONTH(DATEVALUE(A13&" 1"))+1,1)),0)+1-WEEKDAY(EOMONTH((DATE(LEFT(A$1,4),MONTH(DATEVALUE(A13&" 1"))+1,1)),0)+1-4)) -> Jan 25 | N13: 798.12 | Q13: =Q12+F13 -> 7182.4963
A14: 42702 | B14: 28,29,1,2 | C14: =8+6+5+8 -> 27
A15: =A14+7 -> 42709 | B15: 5, 6, 7, 8, 9 | C15: =8+6+3+8+7 -> 32
A16: =A15+7 -> 42716 | B16: 12,13,14,15,16 | C16: =8+6+3+8+8 -> 33
A17: =A16+7 -> 42723 | J17: ="SUM: " & ROUND(SUM(J8:J13),2) -> SUM: 255.08 | L17: ="SUM: "& ROUND(SUM(L2:L13),2) -> SUM: 8324.02 | N17: ="SUM: " & SUM(N2:N13) -> SUM: 8533.95
A19: Hourly Rate: | B19: 7.7996
A20: Bonus Rate | B20: 8.25
A21: Pension | B21: N
A30: 8.5 * 5 | B30: =ROUND((8.5*5)+((8.5*5)/9),2)*52 -> 2455.44 | C30: =B30*8.25 -> 20257.38 | D30: =C30/12 -> 1688.115 | E30: =(D30/4-155)*0.12*4 -> 128.1738 | F30: =ROUND((C30-11000)*0.2,2) -> 1851.48 | G30: =C30-F30-E30 -> 18277.726
A31: 7.5 * 5 | B31: =ROUND((7.5*5)+((7.5*5)/9),2)*52 -> 2166.84 | C31: =B31*8.25 -> 17876.43 | D31: =C31/12 -> 1489.7025 | E31: =(D31/4-155)*0.12*4 -> 104.3643 | F31: =ROUND((C31-11000)*0.2,2) -> 1375.29 | G31: =C31-F31-E31 -> 16396.776
A32: 8.5 * 4 | B32: =37.78*52 -> 1964.56 | C32: =B32*8.25 -> 16207.62 | D32: =C32/12 -> 1350.635 | E32: =(D32/4-155)*0.12*4 -> 87.6762 | F32: =ROUND((C32-11000)*0.2,2) -> 1041.52 | G32: =C32-F32-E32 -> 15078.424
